Workbook

Sheet Sheet1
A1: 中部调度台日运行方案
A2: 日期：2026年4月29日 后端调度员：李扬
A3: 一、当日运行思路
A4: 1.当日调整背景、目标：五一假期前尽量将天然气输送到下游；维持西二三和川气末端压力。 2.运行问题、瓶颈：鲁山机组有故障暂时只能启双机。 3.压缩机组配置：西二三线枣阳上游（海原、灵台）联合运行，预计调整后配置为海(3)彭(0)灵(3)高(2)潼(2)洛(2)鲁(2)枣(2)黄(2)武(1)南(0)抚(1)衢(1)；川气机组配置为普(0)黄金(2)利川(2)野三关(2)宜昌(0)潜江(2)武汉(2)黄梅(2) 4.作业：无。
A7: 二、上下载计划 | C7: ="上载变化量"&INT(B11) -> 上载变化量-25 | M7: ="下载变化量"&N11 -> 下载变化量-232
A8: 上载站场 | B8: 总 | C8: 忠县 | D8: 涪陵增压站 | E8: 涪陵输气站 | F8: 南川输气站 | G8: 普光 | H8: 平昌 | I8: 元坝 | J8: 4#阀室 | K8: 江汉 | L8: 忠义 | M8: 管线下载 | N8: 总 | O8: 西二东 | P8: 忠武线 | Q8: 川气东送 | R8: 新气管道 | S8: 西三线 | T8: 川东北-川西 | U8: 重庆管道
A9: 今日日指定 | B9: 7042.33 | C9: 500 | D9: 216.3 | E9: 873.2 | F9: 877.77 | G9: 1748.3 | H9: 119.06 | I9: 1366.4 | J9: 46.8 | K9: 0 | L9: 1230 | M9: 今日日指定 | N9: 12453.283 | O9: 5067.4828 | P9: 1583.904 | Q9: 4241.096 | R9: 199.74 | S9: 227.35 | T9: 435.56 | U9: 332.15
A10: 昨日日指定 | B10: 7066.74 | C10: 500 | D10: 217 | E10: 873.2 | F10: 920.39 | G10: 1748.1 | H10: 118.55 | I10: 1342.2 | J10: 48.8 | K10: 0 | L10: 1230 | M10: 昨日日指定 | N10: 12685.027 | O10: 5058.4871 | P10: 1641.4 | Q10: 4266.87 | R10: 229.85 | S10: 244.15 | T10: 437.32 | U10: 334.45
A11: 日指定变化 | B11: -25 | C11: 0 | D11: -0.7 | E11: 0 | F11: -42.62 | G11: 0.2 | H11: 0.51 | I11: 24.2 | J11: -2 | K11: 0 | L11: 0 | M11: 日指定变化 | N11: -232 | O11: 8.9957 | P11: -57.496 | Q11: -25.774 | R11: -30.11 | S11: -16.8 | T11: -1.76 | U11: -2.3
A12: 三、平衡预测 | M12: 四、转供量
A13: 管道 | B13: 总 | C13: 西二三线 | D13: 忠武线 | E13: 川气东送 | F13: 川东北-川西 | G13: 新气管道 | H13: 重庆管道 | I13: 今日平衡情况:总平衡-207 二三线-134，忠武线59，川气-422，新气290，其他平。 调整思路：中卫来气压力较低，调整上游机组；维持甪直下载量，川气末端压力较高，通过嘉善转供补甪直方向压力。 | M13: 西二三：中卫5500中卫二站3000薛店-400甪直1400西三转新气仙桃1000西三转忠武仙桃850 忠武线：武汉西200安沙200仙桃750宜昌200 川气：铜梁1230宜昌200潜江400嘉善300南京200 新气：仙桃1000安沙200韶关200桂林250
A14: 当日管存 | B14: 81383.978 | C14: 55142.448 | D14: 2373.7369 | E14: 12799.232 | F14: 1925.9276 | G14: 1279.3671 | H14: 7863.2657
A15: 早8:00平衡 | B15: -206.6 | C15: -134 | D15: 59 | E15: -421.6 | F15: 0 | G15: 290 | H15: 0
A16: 调整后平衡 | B16: -206.6 | C16: -134 | D16: 59 | E16: -421.6 | F16: 0 | G16: 290 | H16: 0
A17: 次日管存预测 | B17: 81177.378 | C17: 55008.448 | D17: 2432.7369 | E17: 12377.632 | F17: 1925.9276 | G17: 1569.3671 | H17: 7863.2657
A18: 五、管道运行参数
A19: 站场 | B19: 进站压力 | C19: 出站压力 | D19: 流量 | E19: 转速 | F19: 台数 | G19: 效率 | H19: 站场 | I19: 进站压力 | J19: 出站压力 | K19: 流量 | L19: 转速 | M19: 台数 | N19: 效率 | O19: 转供站场 | P19: 进站压力 | Q19: 出站压力 | R19: 今日转供 | S19: 能否完成 | T19: 关键点 | U19: 压力
A20: 中卫 | B20: 7.4 | C20: 7.4|7.1 | D20: 5500|3000 | E20: / | F20: / | G20: / | H20: 普光 | I20: 7 | J20: 6.9 | K20: 2344 | L20: / | M20: 0 | N20: / | O20: 南京 | P20: 6 | Q20: 5.1 | R20: =[1]调整策略与目标工况!I14 -> 200 | S20: 能 | T20: 上海 | U20: 7.8
A21: 海原 | B21: 5.9674829 | C21: 7.5 | D21: 8621.0924 | E21: 4200 | F21: 3 | G21: 高 | H21: 黄金 | I21: 6.2 | J21: 8.5 | K21: 2188 | L21: 1370 | M21: 2 | N21: 高 | O21: 姜家湾 | P21: 7.1 | Q21: 6.2 | R21: =[1]调整策略与目标工况!I12 -> 0 | S21: 能 | T21: 金坛 | U21: 7.3
A22: 彭阳 | B22: 6.6039124 | C22: 6.6039124 | D22: 8611.5416 | E22: 0 | F22: 0 | G22: / | H22: 利川 | I22: 6.5 | J22: 8.5 | K22: 3615 | L22: 1400 | M22: 2 | N22: 高 | O22: 嘉善 | P22: 6.8 | Q22: 6.3 | R22: =[1]调整策略与目标工况!D17+[1]调整策略与目标工况!I13 -> 300 | S22: 能 | T22: 樟树 | U22: 7.3
A23: 灵台 | B23: 5.524225 | C23: 8 | D23: 8560.0682 | E23: 4100 | F23: 3 | G23: 高 | H23: 野三关 | I23: 6.5 | J23: 8.6 | K23: 3338 | L23: 1400 | M23: 2 | N23: 高 | O23: 川气潜江 | P23: 7.7 | Q23: 6.7 | R23: =[1]调整策略与目标工况!I20 -> 0 | S23: 能 | T23: 黄冈 | U23: 8.1
A24: 高陵 | B24: 6.7 | C24: 8.3 | D24: 6283.7948 | E24: 4000 | F24: 2 | G24: 高 | H24: 宜昌 | I24: 8 | J24: 7.9 | K24: 3769 | L24: / | M24: 0 | N24: / | O24: 新气仙桃 | P24: 7.8 | Q24: 7.7 | R24: =[1]调整策略与目标工况!I18 -> 1000 | S24: 能 | T24: 黄石 | U24: 3.8
A25: 潼关 | B25: 6.4502641 | C25: 8.3 | D25: 6189.2039 | E25: 4400 | F25: 2 | G25: 高 | H25: 潜江 | I25: 6.6 | J25: 8.1 | K25: 3486 | L25: 1300 | M25: 2 | N25: 高 | O25: 忠武仙桃 | P25: 7.8 | Q25: 5.3 | R25: =[1]调整策略与目标工况!D25 -> 750 | S25: 能 | T25: 商洛 | U25: 6.7
A26: 洛宁 | B26: 6.6219144 | C26: 8.5 | D26: 6147.0606 | E26: 4900 | F26: 2 | G26: 高 | H26: 武汉 | I26: 6.8 | J26: 8.5 | K26: 3753 | L26: 1200 | M26: 2 | N26: 高 | O26: 桂林 | P26: 7.3 | Q26: 7.2 | R26: =[1]调整策略与目标工况!I22 -> 250 | S26: 能 | T26: 兰考 | U26: 6.5
A27: 鲁山 | B27: 6.6 | C27: 8.5 | D27: 5629.9024 | E27: 4300 | F27: 2 | G27: 高 | H27: 黄梅 | I27: 7.3 | J27: 9.3 | K27: 2863 | L27: 1300 | M27: 2 | N27: 高 | O27: 甪直 | P27: 6.7 | Q27: 5.5 | R27: =[1]调整策略与目标工况!D12 -> 1400 | S27: 能
A28: 枣阳 | B28: 6.7752262 | C28: 9 | D28: 7372.4197 | E28: 4300 | F28: 2 | G28: 高 | H28: 元坝 | I28: 3.8 | J28: 7.2 | K28: 742 | L28: 往复式 | M28: 4 | N28: 高 | O28: 安沙 | P28: 7.4 | Q28: 4.1 | R28: =[1]调整策略与目标工况!I19 -> 200 | S28: 能
A29: 黄陂 | B29: 7.5167997 | C29: 8.8 | D29: 5244.5543 | E29: 4500 | F29: 2 | G29: 高 | H29: 涪陵 | I29: 3.8 | J29: 8.5 | K29: 1619 | L29: 12000 | M29: 3 | N29: 高 | O29: 韶关转省网 | P29: 7.3 | Q29: 6 | R29: =[1]调整策略与目标工况!I21 -> 200 | S29: 能
A30: 武穴 | B30: 7.5415452 | C30: 8.7 | D30: 4826.8817 | E30: 4800 | F30: 1 | G30: 高 | H30: 忠县 | I30: 4.1 | J30: 5.8 | K30: 500 | L30: 7650 | M30: 1 | N30: 高 | O30: 韶关转西二 | P30: 8.7 | Q30: 7 | R30: =[1]调整策略与目标工况!I17+[1]调整策略与目标工况!I23 -> 0 | S30: /
A31: 南昌 | B31: 7.6286078 | C31: 7.6286078 | D31: 4710.523 | E31: 0 | F31: 0 | G31: / | H31: 川二铜梁 | I31: 8 | J31: 8 | K31: 1230 | L31: / | M31: 0 | N31: /
A32: 抚州 | B32: 6.7249086 | C32: 8 | D32: 2966.7279 | E32: 3700 | F32: 1 | G32: 高 | H32: 衢州 | I32: 8.2546002 | J32: 9 | K32: 2669.7997 | L32: 3400 | M32: 1 | N32: 高
A33: 六、计划调整
B34: 调整时间 | F34: 调整点 | L34: 调整原因 | Q34: 调整措施
A35: 1 | B35: 0.375 | F35: 灵台 | L35: 根据上游来气，调整机组 | Q35: 停灵台1台机组
A36: 2 | B36: 0.39583333 | F36: 南京、金坛输气站 | L36: 川气末端压力较高 | Q36: 青宁转川气降至200、金坛按5.5MPa控
A37: 3 | B37: 0.43055556 | F37: 洛宁 | L37: 配合洛宁站作业 | Q37: 全站停机6小时
A38: 4
A39: 5
N40: 西二线流量、压力坡降图
C41: ="中卫"&[1]调整策略与目标工况!D8+[1]调整策略与目标工况!D32 -> 中卫8500
J47: ="泰安"&[1]调整策略与目标工况!D9 -> 泰安0
...
