Workbook
Name 白银支线: 管道站场阀室关系!$B$1826
Name 白银支线: #REF!
Name 宝钢支线: 管道站场阀室关系!$B$230
Name 宝钢支线: #REF!
Name 宝香西管道: 管道站场阀室关系!$B$1599
Name 宝香西管道: #REF!
Name 北海支线: 管道站场阀室关系!#REF!
Name 北海支线: #REF!
Name 北疆联络线: 管道站场阀室关系!#REF!
Name 北疆联络线: #REF!
Name 滨州支线: 管道站场阀室关系!#REF!
Name 滨州支线: #REF!
Name 采育通州东支线: 管道站场阀室关系!#REF!
Name 采育通州东支线: #REF!
Name 苍梧贺州支线: 管道站场阀室关系!$B$832
Name 苍梧贺州支线: #REF!
Name 沧淄线干线: 管道站场阀室关系!#REF!
Name 沧淄线干线: #REF!
Name 昌邑支线: 管道站场阀室关系!#REF!
Name 昌邑支线: #REF!
Name 昌邑支线: #REF!
Name 常长支线: 管道站场阀室关系!$B$213
Name 常长支线: #REF!
Name 大连支线: 管道站场阀室关系!$B$1988
Name 大连支线: #REF!
Name 大沈线干线: 管道站场阀室关系!$B$1959
Name 大沈线干线: #REF!
Name 大唐煤制气管道: 管道站场阀室关系!$B$1587
Name 大唐煤制气管道: #REF!
Name 德德支线: 管道站场阀室关系!$B$325
Name 德德支线: #REF!
Name 德武支线: 管道站场阀室关系!$B$323
Name 德武支线: #REF!
Name 定合支线: 管道站场阀室关系!$B$190
Name 定合支线: #REF!
Name 都匀支线: 管道站场阀室关系!$B$2559
Name 都匀支线: #REF!
Name 独石化支线: 管道站场阀室关系!$B$604
Name 独石化支线: #REF!
Name 防城港支线: 管道站场阀室关系!$B$2584
Name 防城港支线: #REF!
Name 抚顺支线: 管道站场阀室关系!$B$1993
Name 抚顺支线: #REF!
Name 甘南支线: 管道站场阀室关系!$B$1736
Name 甘南支线: #REF!
Name 甘南支线支线: 管道站场阀室关系!$B$1743
Name 甘南支线支线: #REF!
Name 甘西南地区供气管道: 管道站场阀室关系!$B$1731
Name 甘西南地区供气管道: #REF!
Name 港沧一线: 管道站场阀室关系!#REF!
Name 港沧一线: #REF!
Name 港沧一线: #REF!
Name 港清复线: 管道站场阀室关系!$B$1419
Name 港清复线: #REF!
Name 港清三线: 管道站场阀室关系!$B$1424
Name 港清三线: #REF!
Name 港清线: 管道站场阀室关系!$B$1409
Name 港清线: #REF!
Name 高丽营西沙屯联络线: 管道站场阀室关系!$B$1580
Name 高丽营西沙屯联络线: #REF!

Sheet 数据统计
B2: 天然气管网基本现状
B3: 管道类型 | C3: 条数 | D3: 里程，km | E3: 站场 | F3: 阀室 | G3: 压气站 | H3: 压缩机
B4: 一级管道 | C4: 55 | D4: =SUMIF(干线管道!C:C,"一级",干线管道!D:D) -> 55638.935 | E4: =SUMIF(干线管道!C:C,"一级",干线管道!F:F) -> 799 | F4: =SUMIF(干线管道!C:C,"一级",干线管道!G:G) -> 2120 | G4: =SUMIF(干线管道!C:C,"一级",干线管道!H:H) -> 110 | H4: =COUNTIFS(压缩机!B:B,"一级",压缩机!R:R,"投产") -> 408
B5: 二级管道 | C5: =COUNTIF(干线管道!C:C,"二级") -> 7 | D5: =SUMIF(干线管道!C:C,"二级",干线管道!D:D) -> 6901.3496 | E5: =SUMIF(干线管道!C:C,"二级",干线管道!F:F) -> 217 | F5: =SUMIF(干线管道!C:C,"二级",干线管道!G:G) -> 302 | G5: =SUMIF(干线管道!C:C,"二级",干线管道!H:H) -> 1 | H5: =COUNTIFS(压缩机!B:B,"二级",压缩机!R:R,"投产") -> 4
B6: 总合计 | C6: =C4+C5 -> 62 | D6: =D4+D5 -> 62540.285 | E6: =E4+E5 -> 1016 | F6: =F4+F5 -> 2422 | G6: =G4+G5 -> 111 | H6: =H4+H5 -> 412
B8: 用户与分输口 | D8: 远控
B9: 供气点 | C9: 937 | E9: 压气站 | F9: 分输站 | G9: 其他站 | H9: 代管站 | I9: RTU阀室
B10: 分输口 | C10: 1633 | D10: 已投运场站总数 | E10: =SUMIF(干线管道!$C:$C,"一级",干线管道!H:H)+SUMIF(干线管道!$C:$C,"二级",干线管道!H:H) -> 111 | F10: =SUMIF(干线管道!$C:$C,"一级",干线管道!I:I)+SUMIF(干线管道!$C:$C,"二级",干线管道!I:I) -> 657 | G10: =SUMIF(干线管道!$C:$C,"一级",干线管道!J:J)+SUMIF(干线管道!$C:$C,"二级",干线管道!J:J) -> 191 | H10: =SUMIF(干线管道!$C:$C,"一级",干线管道!K:K)+SUMIF(干线管道!$C:$C,"二级",干线管道!K:K) -> 57 | I10: =SUMIF(干线管道!$C:$C,"一级",干线管道!L:L)+SUMIF(干线管道!$C:$C,"二级",干线管道!L:L) -> 1695

Sheet 干线管道
A1: 序号 | B1: 干线管道 | C1: 调控级别 | D1: 长度 | E1: 物理管容 | F1: 站场 | G1: 阀室 | H1: 压气站 | I1: 分输站 | J1: 其他站 | K1: 代管站 | L1: 监控阀室 | M1: 监视阀室 | N1: 普通阀室
A2: 1 | B2: 西气东输一线 | C2: 一级 | D2: =SUMIF(管道站场阀室关系!A:A,B2,管道站场阀室关系!H:H) -> 4474.7199 | E2: =SUMIF(管道站场阀室关系!A:A,B2,管道站场阀室关系!J:J) -> 3098264.6 | F2: =SUM(H2:K2) -> 65 | G2: =SUM(L2:N2) -> 158 | H2: =COUNTIFS(管道站场阀室关系!A:A,B2,管道站场阀室关系!P:P,H$1) -> 22 | I2: =COUNTIFS(管道站场阀室关系!A:A,B2,管道站场阀室关系!P:P,I$1) -> 41 | J2: =COUNTIFS(管道站场阀室关系!A:A,B2,管道站场阀室关系!P:P,J$1) -> 2 | K2: =COUNTIFS(管道站场阀室关系!A:A,B2,管道站场阀室关系!P:P,K$1) -> 0 | L2: =COUNTIFS(管道站场阀室关系!A:A,B2,管道站场阀室关系!P:P,L$1) -> 139 | M2: =COUNTIFS(管道站场阀室关系!A:A,B2,管道站场阀室关系!P:P,M$1) -> 2 | N2: =COUNTIFS(管道站场阀室关系!A:A,B2,管道站场阀室关系!P:P,N$1) -> 17
A3: 2 | B3: 冀宁线 | C3: 一级 | D3: =SUMIF(管道站场阀室关系!A:A,B3,管道站场阀室关系!H:H) -> 1331.2707 | E3: =SUMIF(管道站场阀室关系!A:A,B3,管道站场阀室关系!J:J) -> 487778.67 | F3: =SUM(H3:K3) -> 32 | G3: =SUM(L3:N3) -> 45 | H3: =COUNTIFS(管道站场阀室关系!A:A,B3,管道站场阀室关系!P:P,H$1) -> 1 | I3: =COUNTIFS(管道站场阀室关系!A:A,B3,管道站场阀室关系!P:P,I$1) -> 29 | J3: =COUNTIFS(管道站场阀室关系!A:A,B3,管道站场阀室关系!P:P,J$1) -> 0 | K3: =COUNTIFS(管道站场阀室关系!A:A,B3,管道站场阀室关系!P:P,K$1) -> 2 | L3: =COUNTIFS(管道站场阀室关系!A:A,B3,管道站场阀室关系!P:P,L$1) -> 6 | M3: =COUNTIFS(管道站场阀室关系!A:A,B3,管道站场阀室关系!P:P,M$1) -> 1 | N3: =COUNTIFS(管道站场阀室关系!A:A,B3,管道站场阀室关系!P:P,N$1) -> 38
A4: 3 | B4: 江苏LNG外输管道 | C4: 一级 | D4: =SUMIF(管道站场阀室关系!A:A,B4,管道站场阀室关系!H:H) -> 391.877 | E4: =SUMIF(管道站场阀室关系!A:A,B4,管道站场阀室关系!J:J) -> 250339.45 | F4: =SUM(H4:K4) -> 10 | G4: =SUM(L4:N4) -> 20 | H4: =COUNTIFS(管道站场阀室关系!A:A,B4,管道站场阀室关系!P:P,H$1) -> 0 | I4: =COUNTIFS(管道站场阀室关系!A:A,B4,管道站场阀室关系!P:P,I$1) -> 9 | J4: =COUNTIFS(管道站场阀室关系!A:A,B4,管道站场阀室关系!P:P,J$1) -> 1 | K4: =COUNTIFS(管道站场阀室关系!A:A,B4,管道站场阀室关系!P:P,K$1) -> 0 | L4: =COUNTIFS(管道站场阀室关系!A:A,B4,管道站场阀室关系!P:P,L$1) -> 18 | M4: =COUNTIFS(管道站场阀室关系!A:A,B4,管道站场阀室关系!P:P,M$1) -> 2 | N4: =COUNTIFS(管道站场阀室关系!A:A,B4,管道站场阀室关系!P:P,N$1) -> 0
A5: 4 | B5: 淮武线 | C5: 一级 | D5: =SUMIF(管道站场阀室关系!A:A,B5,管道站场阀室关系!H:H) -> 436.889 | E5: =SUMIF(管道站场阀室关系!A:A,B5,管道站场阀室关系!J:J) -> 116059 | F5: =SUM(H5:K5) -> 3 | G5: =SUM(L5:N5) -> 21 | H5: =COUNTIFS(管道站场阀室关系!A:A,B5,管道站场阀室关系!P:P,H$1) -> 0 | I5: =COUNTIFS(管道站场阀室关系!A:A,B5,管道站场阀室关系!P:P,I$1) -> 3 | J5: =COUNTIFS(管道站场阀室关系!A:A,B5,管道站场阀室关系!P:P,J$1) -> 0 | K5: =COUNTIFS(管道站场阀室关系!A:A,B5,管道站场阀室关系!P:P,K$1) -> 0 | L5: =COUNTIFS(管道站场阀室关系!A:A,B5,管道站场阀室关系!P:P,L$1) -> 8 | M5: =COUNTIFS(管道站场阀室关系!A:A,B5,管道站场阀室关系!P:P,M$1) -> 0 | N5: =COUNTIFS(管道站场阀室关系!A:A,B5,管道站场阀室关系!P:P,N$1) -> 13
A6: 5 | B6: 西气东输二线 | C6: 一级 | D6: =SUMIF(管道站场阀室关系!A:A,B6,管道站场阀室关系!H:H) -> 5098.0123 | E6: =SUMIF(管道站场阀室关系!A:A,B6,管道站场阀室关系!J:J) -> 5365107.9 | F6: =SUM(H6:K6) -> 64 | G6: =SUM(L6:N6) -> 150 | H6: =COUNTIFS(管道站场阀室关系!A:A,B6,管道站场阀室关系!P:P,H$1) -> 27 | I6: =COUNTIFS(管道站场阀室关系!A:A,B6,管道站场阀室关系!P:P,I$1) -> 36 | J6: =COUNTIFS(管道站场阀室关系!A:A,B6,管道站场阀室关系!P:P,J$1) -> 1 | K6: =COUNTIFS(管道站场阀室关系!A:A,B6,管道站场阀室关系!P:P,K$1) -> 0 | L6: =COUNTIFS(管道站场阀室关系!A:A,B6,管道站场阀室关系!P:P,L$1) -> 33 | M6: =COUNTIFS(管道站场阀室关系!A:A,B6,管道站场阀室关系!P:P,M$1) -> 116 | N6: =COUNTIFS(管道站场阀室关系!A:A,B6,管道站场阀室关系!P:P,N$1) -> 1
A7: 6 | B7: 轮吐支干线 | C7: 一级 | D7: =SUMIF(管道站场阀室关系!A:A,B7,管道站场阀室关系!H:H) -> 524 | E7: =SUMIF(管道站场阀室关系!A:A,B7,管道站场阀室关系!J:J) -> 424150 | F7: =SUM(H7:K7) -> 1 | G7: =SUM(L7:N7) -> 15 | H7: =COUNTIFS(管道站场阀室关系!A:A,B7,管道站场阀室关系!P:P,H$1) -> 1 | I7: =COUNTIFS(管道站场阀室关系!A:A,B7,管道站场阀室关系!P:P,I$1) -> 0 | J7: =COUNTIFS(管道站场阀室关系!A:A,B7,管道站场阀室关系!P:P,J$1) -> 0 | K7: =COUNTIFS(管道站场阀室关系!A:A,B7,管道站场阀室关系!P:P,K$1) -> 0 | L7: =COUNTIFS(管道站场阀室关系!A:A,B7,管道站场阀室关系!P:P,L$1) -> 3 | M7: =COUNTIFS(管道站场阀室关系!A:A,B7,管道站场阀室关系!P:P,M$1) -> 12 | N7: =COUNTIFS(管道站场阀室关系!A:A,B7,管道站场阀室关系!P:P,N$1) -> 0
A8: 7 | B8: 中靖支干线 | C8: 一级 | D8: =SUMIF(管道站场阀室关系!A:A,B8,管道站场阀室关系!H:H) -> 335.4 | E8: =SUMIF(管道站场阀室关系!A:A,B8,管道站场阀室关系!J:J) -> 262751.21 | F8: =SUM(H8:K8) -> 2 | G8: =SUM(L8:N8) -> 12 | H8: =COUNTIFS(管道站场阀室关系!A:A,B8,管道站场阀室关系!P:P,H$1) -> 0 | I8: =COUNTIFS(管道站场阀室关系!A:A,B8,管道站场阀室关系!P:P,I$1) -> 2 | J8: =COUNTIFS(管道站场阀室关系!A:A,B8,管道站场阀室关系!P:P,J$1) -> 0 | K8: =COUNTIFS(管道站场阀室关系!A:A,B8,管道站场阀室关系!P:P,K$1) -> 0 | L8: =COUNTIFS(管道站场阀室关系!A:A,B8,管道站场阀室关系!P:P,L$1) -> 0 | M8: =COUNTIFS(管道站场阀室关系!A:A,B8,管道站场阀室关系!P:P,M$1) -> 12 | N8: =COUNTIFS(管道站场阀室关系!A:A,B8,管道站场阀室关系!P:P,N$1) -> 0
A9: 8 | B9: 枣十支干线 | C9: 一级 | D9: =SUMIF(管道站场阀室关系!A:A,B9,管道站场阀室关系!H:H) -> 206.1798 | E9: =SUMIF(管道站场阀室关系!A:A,B9,管道站场阀室关系!J:J) -> 38420.46 | F9: =SUM(H9:K9) -> 7 | G9: =SUM(L9:N9) -> 11 | H9: =COUNTIFS(管道站场阀室关系!A:A,B9,管道站场阀室关系!P:P,H$1) -> 0 | I9: =COUNTIFS(管道站场阀室关系!A:A,B9,管道站场阀室关系!P:P,I$1) -> 7 | J9: =COUNTIFS(管道站场阀室关系!A:A,B9,管道站场阀室关系!P:P,J$1) -> 0 | K9: =COUNTIFS(管道站场阀室关系!A:A,B9,管道站场阀室关系!P:P,K$1) -> 0 | L9: =COUNTIFS(管道站场阀室关系!A:A,B9,管道站场阀室关系!P:P,L$1) -> 5 | M9: =COUNTIFS(管道站场阀室关系!A:A,B9,管道站场阀室关系!P:P,M$1) -> 6 | N9: =COUNTIFS(管道站场阀室关系!A:A,B9,管道站场阀室关系!P:P,N$1) -> 0
A10: 9 | B10: 樟湘支干线 | C10: 一级 | D10: =SUMIF(管道站场阀室关系!A:A,B10,管道站场阀室关系!H:H) -> 262.2999 | E10: =SUMIF(管道站场阀室关系!A:A,B10,管道站场阀室关系!J:J) -> 81166.319 | F10: =SUM(H10:K10) -> 8 | G10: =SUM(L10:N10) -> 10 | H10: =COUNTIFS(管道站场阀室关系!A:A,B10,管道站场阀室关系!P:P,H$1) -> 1 | I10: =COUNTIFS(管道站场阀室关系!A:A,B10,管道站场阀室关系!P:P,I$1) -> 7 | J10: =COUNTIFS(管道站场阀室关系!A:A,B10,管道站场阀室关系!P:P,J$1) -> 0 | K10: =COUNTIFS(管道站场阀室关系!A:A,B10,管道站场阀室关系!P:P,K$1) -> 0 | L10: =COUNTIFS(管道站场阀室关系!A:A,B10,管道站场阀室关系!P:P,L$1) -> 3 | M10: =COUNTIFS(管道站场阀室关系!A:A,B10,管道站场阀室关系!P:P,M$1) -> 7 | N10: =COUNTIFS(管道站场阀室关系!A:A,B10,管道站场阀室关系!P:P,N$1) -> 0
A11: 10 | B11: 上海支干线 | C11: 一级 | D11: =SUMIF(管道站场阀室关系!A:A,B11,管道站场阀室关系!H:H) -> 902.8247 | E11: =SUMIF(管道站场阀室关系!A:A,B11,管道站场阀室关系!J:J) -> 687510.59 | F11: =SUM(H11:K11) -> 13 | G11: =SUM(L11:N11) -> 49 | H11: =COUNTIFS(管道站场阀室关系!A:A,B11,管道站场阀室关系!P:P,H$1) -> 2 | I11: =COUNTIFS(管道站场阀室关系!A:A,B11,管道站场阀室关系!P:P,I$1) -> 11 | J11: =COUNTIFS(管道站场阀室关系!A:A,B11,管道站场阀室关系!P:P,J$1) -> 0 | K11: =COUNTIFS(管道站场阀室关系!A:A,B11,管道站场阀室关系!P:P,K$1) -> 0 | L11: =COUNTIFS(管道站场阀室关系!A:A,B11,管道站场阀室关系!P:P,L$1) -> 20 | M11: =COUNTIFS(管道站场阀室关系!A:A,B11,管道站场阀室关系!P:P,M$1) -> 29 | N11: =COUNTIFS(管道站场阀室关系!A:A,B11,管道站场阀室关系!P:P,N$1) -> 0
A12: 11 | B12: 平泰支干线 | C12: 一级 | D12: =SUMIF(管道站场阀室关系!A:A,B12,管道站场阀室关系!H:H) -> 570.9099 | E12: =SUMIF(管道站场阀室关系!A:A,B12,管道站场阀室关系!J:J) -> 398273.48 | F12: =SUM(H12:K12) -> 9 | G12: =SUM(L12:N12) -> 17 | H12: =COUNTIFS(管道站场阀室关系!A:A,B12,管道站场阀室关系!P:P,H$1) -> 1 | I12: =COUNTIFS(管道站场阀室关系!A:A,B12,管道站场阀室关系!P:P,I$1) -> 8 | J12: =COUNTIFS(管道站场阀室关系!A:A,B12,管道站场阀室关系!P:P,J$1) -> 0 | K12: =COUNTIFS(管道站场阀室关系!A:A,B12,管道站场阀室关系!P:P,K$1) -> 0 | L12: =COUNTIFS(管道站场阀室关系!A:A,B12,管道站场阀室关系!P:P,L$1) -> 5 | M12: =COUNTIFS(管道站场阀室关系!A:A,B12,管道站场阀室关系!P:P,M$1) -> 12 | N12: =COUNTIFS(管道站场阀室关系!A:A,B12,管道站场阀室关系!P:P,N$1) -> 0
A13: 12 | B13: 广南支干线 | C13: 一级 | D13: =SUMIF(管道站场阀室关系!A:A,B13,管道站场阀室关系!H:H) -> 1327.0113 | E13: =SUMIF(管道站场阀室关系!A:A,B13,管道站场阀室关系!J:J) -> 579597.54 | F13: =SUM(H13:K13) -> 21 | G13: =SUM(L13:N13) -> 53 | H13: =COUNTIFS(管道站场阀室关系!A:A,B13,管道站场阀室关系!P:P,H$1) -> 1 | I13: =COUNTIFS(管道站场阀室关系!A:A,B13,管道站场阀室关系!P:P,I$1) -> 14 | J13: =COUNTIFS(管道站场阀室关系!A:A,B13,管道站场阀室关系!P:P,J$1) -> 2 | K13: =COUNTIFS(管道站场阀室关系!A:A,B13,管道站场阀室关系!P:P,K$1) -> 4 | L13: =COUNTIFS(管道站场阀室关系!A:A,B13,管道站场阀室关系!P:P,L$1) -> 36 | M13: =COUNTIFS(管道站场阀室关系!A:A,B13,管道站场阀室关系!P:P,M$1) -> 17 | N13: =COUNTIFS(管道站场阀室关系!A:A,B13,管道站场阀室关系!P:P,N$1) -> 0
... A57: 56 | B57: 漳州LNG外输管道 | C57: 一级 | D57: =SUMIF(管道站场阀室关系!A:A,B57,管道站场阀室关系!H:H) -> 123.25 | E57: =SUMIF(管道站场阀室关系!A:A,B57,管道站场阀室关系!J:J) -> 85360.55 | F57: =SUM(H57:K57) -> 2 | G57: =SUM(L57:N57) -> 5 | H57: =COUNTIFS(管道站场阀室关系!A:A,B57,管道站场阀室关系!P:P,H$1) -> 0 | I57: =COUNTIFS(管道站场阀室关系!A:A,B57,管道站场阀室关系!P:P,I$1) -> 2 | J57: =COUNTIFS(管道站场阀室关系!A:A,B57,管道站场阀室关系!P:P,J$1) -> 0 | K57: =COUNTIFS(管道站场阀室关系!A:A,B57,管道站场阀室关系!P:P,K$1) -> 0 | L57: =COUNTIFS(管道站场阀室关系!A:A,B57,管道站场阀室关系!P:P,L$1) -> 5 | M57: =COUNTIFS(管道站场阀室关系!A:A,B57,管道站场阀室关系!P:P,M$1) -> 0 | N57: =COUNTIFS(管道站场阀室关系!A:A,B57,管道站场阀室关系!P:P,N$1) -> 0
A58: 57 | B58: 广东省管网 | C58: 二级 | D58: 1989.464 | E58: 1503624 | F58: 59 | G58: =SUM(L58:N58) -> 77 | H58: =COUNTIFS(管道站场阀室关系!A:A,B58,管道站场阀室关系!P:P,H$1) -> 0 | I58: 43 | J58: 15 | K58: =COUNTIFS(管道站场阀室关系!A:A,B58,管道站场阀室关系!P:P,K$1) -> 1 | L58: =COUNTIFS(管道站场阀室关系!A:A,B58,管道站场阀室关系!P:P,L$1) -> 77 | M58: =COUNTIFS(管道站场阀室关系!A:A,B58,管道站场阀室关系!P:P,M$1) -> 0 | N58: =COUNTIFS(管道站场阀室关系!A:A,B58,管道站场阀室关系!P:P,N$1) -> 0
B59: 广东省管网（新丰专线） | C59: 一级 | D59: 15.474 | E59: 1173 | F59: 2 | G59: 0 | H59: 0 | I59: 1 | J59: 1 | K59: 0 | L59: 0 | M59: 0 | N59: 0
A60: 58 | B60: 粤东LNG外输管道 | C60: 二级 | D60: =SUMIF(管道站场阀室关系!A:A,B60,管道站场阀室关系!H:H) -> 179.28 | E60: =SUMIF(管道站场阀室关系!A:A,B60,管道站场阀室关系!J:J) -> 93041 | F60: =SUM(H60:K60) -> 9 | G60: =SUM(L60:N60) -> 5 | H60: =COUNTIFS(管道站场阀室关系!A:A,B60,管道站场阀室关系!P:P,H$1) -> 0 | I60: =COUNTIFS(管道站场阀室关系!A:A,B60,管道站场阀室关系!P:P,I$1) -> 2 | J60: =COUNTIFS(管道站场阀室关系!A:A,B60,管道站场阀室关系!P:P,J$1) -> 7 | K60: =COUNTIFS(管道站场阀室关系!A:A,B60,管道站场阀室关系!P:P,K$1) -> 0 | L60: =COUNTIFS(管道站场阀室关系!A:A,B60,管道站场阀室关系!P:P,L$1) -> 5 | M60: =COUNTIFS(管道站场阀室关系!A:A,B60,管道站场阀室关系!P:P,M$1) -> 0 | N60: =COUNTIFS(管道站场阀室关系!A:A,B60,管道站场阀室关系!P:P,N$1) -> 0
A61: 59 | B61: 浙江省管网 | C61: 二级 | D61: =SUMIF(管道站场阀室关系!A:A,B61,管道站场阀室关系!H:H) -> 2493.8877 | E61: =SUMIF(管道站场阀室关系!A:A,B61,管道站场阀室关系!J:J) -> 959122 | F61: =SUM(H61:K61) -> 91 | G61: =SUM(L61:N61) -> 119 | H61: =COUNTIFS(管道站场阀室关系!A:A,B61,管道站场阀室关系!P:P,H$1) -> 0 | I61: =COUNTIFS(管道站场阀室关系!A:A,B61,管道站场阀室关系!P:P,I$1) -> 75 | J61: =COUNTIFS(管道站场阀室关系!A:A,B61,管道站场阀室关系!P:P,J$1) -> 16 | K61: =COUNTIFS(管道站场阀室关系!A:A,B61,管道站场阀室关系!P:P,K$1) -> 0 | L61: =COUNTIFS(管道站场阀室关系!A:A,B61,管道站场阀室关系!P:P,L$1) -> 119 | M61: =COUNTIFS(管道站场阀室关系!A:A,B61,管道站场阀室关系!P:P,M$1) -> 0 | N61: =COUNTIFS(管道站场阀室关系!A:A,B61,管道站场阀室关系!P:P,N$1) -> 0
A62: 60 | B62: 湖南省管网 | C62: 二级 | D62: =SUMIF(管道站场阀室关系!A:A,B62,管道站场阀室关系!H:H) -> 957.4799 | E62: =SUMIF(管道站场阀室关系!A:A,B62,管道站场阀室关系!J:J) -> 0 | F62: =SUM(H62:K62) -> 24 | G62: =SUM(L62:N62) -> 50 | H62: =COUNTIFS(管道站场阀室关系!A:A,B62,管道站场阀室关系!P:P,H$1) -> 0 | I62: =COUNTIFS(管道站场阀室关系!A:A,B62,管道站场阀室关系!P:P,I$1) -> 18 | J62: =COUNTIFS(管道站场阀室关系!A:A,B62,管道站场阀室关系!P:P,J$1) -> 6 | K62: =COUNTIFS(管道站场阀室关系!A:A,B62,管道站场阀室关系!P:P,K$1) -> 0 | L62: =COUNTIFS(管道站场阀室关系!A:A,B62,管道站场阀室关系!P:P,L$1) -> 35 | M62: =COUNTIFS(管道站场阀室关系!A:A,B62,管道站场阀室关系!P:P,M$1) -> 3 | N62: =COUNTIFS(管道站场阀室关系!A:A,B62,管道站场阀室关系!P:P,N$1) -> 12
A63: 61 | B63: 贵州省管网 | C63: 二级 | D63: =SUMIF(管道站场阀室关系!A:A,B63,管道站场阀室关系!H:H) -> 92.379 | E63: =SUMIF(管道站场阀室关系!A:A,B63,管道站场阀室关系!J:J) -> 5680.983 | F63: =SUM(H63:K63) -> 15 | G63: =SUM(L63:N63) -> 1 | H63: =COUNTIFS(管道站场阀室关系!A:A,B63,管道站场阀室关系!P:P,H$1) -> 0 | I63: =COUNTIFS(管道站场阀室关系!A:A,B63,管道站场阀室关系!P:P,I$1) -> 14 | J63: =COUNTIFS(管道站场阀室关系!A:A,B63,管道站场阀室关系!P:P,J$1) -> 1 | K63: =COUNTIFS(管道站场阀室关系!A:A,B63,管道站场阀室关系!P:P,K$1) -> 0 | L63: =COUNTIFS(管道站场阀室关系!A:A,B63,管道站场阀室关系!P:P,L$1) -> 0 | M63: =COUNTIFS(管道站场阀室关系!A:A,B63,管道站场阀室关系!P:P,M$1) -> 0 | N63: =COUNTIFS(管道站场阀室关系!A:A,B63,管道站场阀室关系!P:P,N$1) -> 1
A64: 62 | B64: 鄯乌线 | C64: 二级 | D64: =SUMIF(管道站场阀室关系!A:A,B64,管道站场阀室关系!H:H) -> 301.73 | E64: =SUMIF(管道站场阀室关系!A:A,B64,管道站场阀室关系!J:J) -> 47355 | F64: =SUM(H64:K64) -> 5 | G64: =SUM(L64:N64) -> 7 | H64: =COUNTIFS(管道站场阀室关系!A:A,B64,管道站场阀室关系!P:P,H$1) -> 1 | I64: =COUNTIFS(管道站场阀室关系!A:A,B64,管道站场阀室关系!P:P,I$1) -> 3 | J64: =COUNTIFS(管道站场阀室关系!A:A,B64,管道站场阀室关系!P:P,J$1) -> 1 | K64: =COUNTIFS(管道站场阀室关系!A:A,B64,管道站场阀室关系!P:P,K$1) -> 0 | L64: =COUNTIFS(管道站场阀室关系!A:A,B64,管道站场阀室关系!P:P,L$1) -> 0 | M64: =COUNTIFS(管道站场阀室关系!A:A,B64,管道站场阀室关系!P:P,M$1) -> 7 | N64: =COUNTIFS(管道站场阀室关系!A:A,B64,管道站场阀室关系!P:P,N$1) -> 0
B65: 注：广东省管网和广东省管网（新丰专线）数据非公式取值。广东省管网（新丰专线）不计入干线条数。

Sheet 支线管道
A1: [原始]序号 | B1: [关联]干线管道 | C1: [原始]支线管道 | D1: [原始]起点 | E1: [原始]终点 | F1: [计算]长度/km | G1: [原始]管径/mm | H1: [原始]主要壁厚/mm | I1: [原始]设计压力/MPa | J1: [原始]设计输量/108m3/a | K1: [原始]设计输量/104m3/d | L1: [计算]物理管容/m3 | M1: [原始]管道投产时间 | N1: [关联]调度台 | O1: [原始]备注
A2: 1 | B2: 西气东输一线 | C2: 西一线干线新疆段 | D2: 轮南压气站 | E2: 红柳压气站 | F2: =SUMIF(管道站场阀室关系!B:B,支线管道!C2,管道站场阀室关系!H:H) -> 954.9577 | G2: 1016 | H2: 14 | I2: 10 | J2: 170 | L2: =SUMIF(管道站场阀室关系!B:B,支线管道!C2,管道站场阀室关系!J:J) -> 711669 | M2: 20041001 | N2: 西部
A3: 2 | B3: 西气东输一线 | C3: 西一线干线甘肃段 | D3: 红柳压气站 | E3: 中卫压气站 | F3: =SUMIF(管道站场阀室关系!B:B,支线管道!C3,管道站场阀室关系!H:H) -> 1028.9439 | G3: 1016 | H3: 14 | I3: 10 | J3: 170 | L3: =SUMIF(管道站场阀室关系!B:B,支线管道!C3,管道站场阀室关系!J:J) -> 810642.05 | M3: 20041001 | N3: 西部
A4: 3 | B4: 西气东输一线 | C4: 西一线干线东段 | D4: 中卫压气站 | E4: 白鹤末站 | F4: =SUMIF(管道站场阀室关系!B:B,支线管道!C4,管道站场阀室关系!H:H) -> 1862.2965 | G4: 1016 | H4: 14 | I4: 10 | J4: 170 | L4: =SUMIF(管道站场阀室关系!B:B,支线管道!C4,管道站场阀室关系!J:J) -> 1392366.5 | M4: 20041001 | N4: 东部
A5: 4 | B5: 西气东输一线 | C5: 常长支线 | D5: 芙蓉分输站 | E5: 长兴末站 | F5: =SUMIF(管道站场阀室关系!B:B,支线管道!C5,管道站场阀室关系!H:H) -> 99.6003 | G5: 813 | I5: 6.4 | J5: 17.86 | L5: =SUMIF(管道站场阀室关系!B:B,支线管道!C5,管道站场阀室关系!J:J) -> 48562.526 | M5: 20031218 | N5: 东部
A6: 5 | B6: 西气东输一线 | C6: 南芜支线 | D6: 西一线南京站 | E6: 芜湖末站 | F6: =SUMIF(管道站场阀室关系!B:B,支线管道!C6,管道站场阀室关系!H:H) -> 130 | G6: 508 | H6: 7.1 | I6: 6.3 | J6: 16.71 | L6: =SUMIF(管道站场阀室关系!B:B,支线管道!C6,管道站场阀室关系!J:J) -> 24780.719 | M6: 200405 | N6: 东部
A7: 6 | B7: 西气东输一线 | C7: 金陵电厂支线 | D7: 西一线南京站 | E7: 金陵电厂 | F7: =SUMIF(管道站场阀室关系!B:B,支线管道!C7,管道站场阀室关系!H:H) -> 3.696 | L7: =SUMIF(管道站场阀室关系!B:B,支线管道!C7,管道站场阀室关系!J:J) -> 320.656 | N7: 东部
A8: 7 | B8: 西气东输一线 | C8: 定合支线 | D8: 定远压气站 | E8: 合肥末站 | F8: =SUMIF(管道站场阀室关系!B:B,支线管道!C8,管道站场阀室关系!H:H) -> 79.5999 | G8: 406.4 | H8: 6.3 | I8: 6.3 | J8: 3.28 | L8: =SUMIF(管道站场阀室关系!B:B,支线管道!C8,管道站场阀室关系!J:J) -> 9989.0904 | M8: 200306 | N8: 东部
A9: 8 | B9: 西气东输一线 | C9: 定合复线 | D9: 定远压气站 | E9: 合肥北站 | F9: =SUMIF(管道站场阀室关系!B:B,支线管道!C9,管道站场阀室关系!H:H) -> 67.2999 | G9: 711 | H9: 14.3/15.9/20.6 | I9: 10 | J9: 34.89 | L9: =SUMIF(管道站场阀室关系!B:B,支线管道!C9,管道站场阀室关系!J:J) -> 26730.737 | M9: 20191106 | N9: 东部
A10: 9 | B10: 西气东输一线 | C10: 扬巴支线 | D10: 龙池分输站 | E10: 扬子扬巴末站 | F10: =SUMIF(管道站场阀室关系!B:B,支线管道!C10,管道站场阀室关系!H:H) -> 6.2 | G10: 406.4 | I10: 10 | J10: 15 | L10: =SUMIF(管道站场阀室关系!B:B,支线管道!C10,管道站场阀室关系!J:J) -> 718.22538 | M10: 200312 | N10: 东部
A11: 10 | B11: 西气东输一线 | C11: 长铝支线 | D11: 郑州压气站 | E11: 长铝末站 | F11: =SUMIF(管道站场阀室关系!B:B,支线管道!C11,管道站场阀室关系!H:H) -> 24 | G11: 219 | I11: 6.4 | J11: 1 | L11: =SUMIF(管道站场阀室关系!B:B,支线管道!C11,管道站场阀室关系!J:J) -> 934 | M11: 20040630 | N11: 东部
A12: 11 | B12: 西气东输一线 | C12: 望亭电厂支线 | D12: 东桥分输站 | E12: 望亭分输站 | F12: =SUMIF(管道站场阀室关系!B:B,支线管道!C12,管道站场阀室关系!H:H) -> 8.2 | G12: 508 | I12: 10 | J12: 10 | L12: =SUMIF(管道站场阀室关系!B:B,支线管道!C12,管道站场阀室关系!J:J) -> 1481.9348 | M12: 200506 | N12: 东部
A13: 12 | B13: 西气东输一线 | C13: 甪宝支线 | D13: 甪直分输站 | E13: 浏河分输站 | F13: =SUMIF(管道站场阀室关系!B:B,支线管道!C13,管道站场阀室关系!H:H) -> 80.219 | G13: 610 | I13: 4 | J13: 20 | L13: =SUMIF(管道站场阀室关系!B:B,支线管道!C13,管道站场阀室关系!J:J) -> 23909.55 | M13: 20110816 | N13: 东部
A14: 13 | B14: 西气东输一线 | C14: 金坛储气库支线 | D14: 镇江分输站 | E14: 金坛分输站 | F14: =SUMIF(管道站场阀室关系!B:B,支线管道!C14,管道站场阀室关系!H:H) -> 34.81 | G14: 1016 | H14: 26 | I14: 10 | J14: - | L14: =SUMIF(管道站场阀室关系!B:B,支线管道!C14,管道站场阀室关系!J:J) -> 25726.619 | M14: 20070101 | N14: 东部
A15: 14 | B15: 西气东输一线 | C15: 金溧支线 | D15: 金坛分输站 | E15: 南渡分输站 | F15: =SUMIF(管道站场阀室关系!B:B,支线管道!C15,管道站场阀室关系!H:H) -> 52.3467 | G15: 508 | I15: 6.3 | J15: 21.66 | L15: =SUMIF(管道站场阀室关系!B:B,支线管道!C15,管道站场阀室关系!J:J) -> 10084.375 | M15: 20160612 | N15: 东部
A16: 15 | B16: 西气东输一线 | C16: 沁水煤层气管道 | D16: 端氏首站 | E16: 沁水压气站 | F16: =SUMIF(管道站场阀室关系!B:B,支线管道!C16,管道站场阀室关系!H:H) -> 35 | G16: 610 | H16: 8 | I16: 6.3 | J16: 30 | L16: =SUMIF(管道站场阀室关系!B:B,支线管道!C16,管道站场阀室关系!J:J) -> 9668 | M16: 20090915 | N16: 东部
A17: 16 | B17: 西气东输一线 | C17: 长江备用线 | D17: 青山分输站 | E17: 龙潭站上游1.5km | F17: =SUMIF(管道站场阀室关系!B:B,支线管道!C17,管道站场阀室关系!H:H) -> 5.8 | G17: 406.4 | L17: =SUMIF(管道站场阀室关系!B:B,支线管道!C17,管道站场阀室关系!J:J) -> 0 | N17: 东部
A18: 17 | B18: 西气东输一线 | C18: 西一线与青宁线青山-南京联络线 | D18: 青山分输站 | E18: 南京末站 | F18: =SUMIF(管道站场阀室关系!B:B,支线管道!C18,管道站场阀室关系!H:H) -> 1.25 | L18: =SUMIF(管道站场阀室关系!B:B,支线管道!C18,管道站场阀室关系!J:J) -> 680.64
A19: 18 | B19: 西气东输一线 | C19: 南京计量中心支线 | D19: 龙潭分输站 | E19: 南京计量中心 | F19: =SUMIF(管道站场阀室关系!B:B,支线管道!C19,管道站场阀室关系!H:H) -> 0.5 | L19: =SUMIF(管道站场阀室关系!B:B,支线管道!C19,管道站场阀室关系!J:J) -> 0
A20: 19 | B20: 冀宁线 | C20: 冀宁线干线冀鲁段 | D20: 泰安分输站 | E20: 安平压气站 | F20: =SUMIF(管道站场阀室关系!B:B,支线管道!C20,管道站场阀室关系!H:H) -> 530.476 | G20: 1016 | H20: 17.5 | I20: 10 | J20: 110 | L20: =SUMIF(管道站场阀室关系!B:B,支线管道!C20,管道站场阀室关系!J:J) -> 273090 | M20: 20060115 | N20: 东部
A21: 20 | B21: 冀宁线 | C21: 冀宁线干线苏北段 | D21: 青山分输站 | E21: 泰安分输站 | F21: =SUMIF(管道站场阀室关系!B:B,支线管道!C21,管道站场阀室关系!H:H) -> 386.5989 | G21: 711 | H21: 12.3 | I21: 10 | J21: 110 | L21: =SUMIF(管道站场阀室关系!B:B,支线管道!C21,管道站场阀室关系!J:J) -> 138439.3 | M21: 20060115 | N21: 东部
A22: 21 | B22: 冀宁线 | C22: 临沂支线 | D22: 滕州分输站 | E22: 临沂末站 | F22: =SUMIF(管道站场阀室关系!B:B,支线管道!C22,管道站场阀室关系!H:H) -> 90.5009 | G22: 406.4 | I22: 6.3 | J22: 6.5 | L22: =SUMIF(管道站场阀室关系!B:B,支线管道!C22,管道站场阀室关系!J:J) -> 10707 | M22: 20060710 | N22: 东部
A23: 22 | B23: 冀宁线 | C23: 济宁支线 | D23: 曲阜分输站 | E23: 济宁末站 | F23: =SUMIF(管道站场阀室关系!B:B,支线管道!C23,管道站场阀室关系!H:H) -> 40.21 | G23: 323.9 | I23: 6.3 | J23: 7.5 | L23: =SUMIF(管道站场阀室关系!B:B,支线管道!C23,管道站场阀室关系!J:J) -> 3060 | M23: 200710 | N23: 东部
A24: 23 | B24: 冀宁线 | C24: 邳徐支线 | D24: 邳州压气站 | E24: 徐州分输站 | F24: =SUMIF(管道站场阀室关系!B:B,支线管道!C24,管道站场阀室关系!H:H) -> 55.1159 | G24: 610 | I24: 10 | J24: 11.79 | L24: =SUMIF(管道站场阀室关系!B:B,支线管道!C24,管道站场阀室关系!J:J) -> 14964.372 | M24: 20070130 | N24: 东部
A25: 24 | B25: 冀宁线 | C25: 邳连支线 | D25: 邳州压气站 | E25: 连云港分输站 | F25: =SUMIF(管道站场阀室关系!B:B,支线管道!C25,管道站场阀室关系!H:H) -> 139.869 | G25: 610 | I25: 10 | J25: 4.4 | L25: =SUMIF(管道站场阀室关系!B:B,支线管道!C25,管道站场阀室关系!J:J) -> 39154.1 | M25: 20061206 | N25: 东部
A26: 25 | B26: 冀宁线 | C26: 武城支线 | D26: 德州分输站 | E26: 武城末站 | F26: =SUMIF(管道站场阀室关系!B:B,支线管道!C26,管道站场阀室关系!H:H) -> 18.39 | G26: 168.3 | I26: 6.3 | J26: 4.5 | L26: =SUMIF(管道站场阀室关系!B:B,支线管道!C26,管道站场阀室关系!J:J) -> 338 | M26: 200610 | N26: 东部
A27: 26 | B27: 冀宁线 | C27: 德州支线 | D27: 德州分输站 | E27: 德州末站 | F27: =SUMIF(管道站场阀室关系!B:B,支线管道!C27,管道站场阀室关系!H:H) -> 15.11 | G27: 219.1 | I27: 6.3 | J27: 5 | L27: =SUMIF(管道站场阀室关系!B:B,支线管道!C27,管道站场阀室关系!J:J) -> 512 | M27: 200706 | N27: 东部
A28: 27 | B28: 冀宁线 | C28: 泰安站联络线 | D28: 泰安压气站 | E28: 泰安分输站 | F28: =SUMIF(管道站场阀室关系!B:B,支线管道!C28,管道站场阀室关系!H:H) -> 7 | G28: 1016 | I28: 10 | J28: 110 | L28: =SUMIF(管道站场阀室关系!B:B,支线管道!C28,管道站场阀室关系!J:J) -> 0 | N28: 东部
A29: 28 | B29: 冀宁线 | C29: 刘庄储气库支线 | D29: 淮安分输站 | E29: 刘庄储气库 | F29: =SUMIF(管道站场阀室关系!B:B,支线管道!C29,管道站场阀室关系!H:H) -> 48 | G29: 457 | I29: 10 | J29: 1 | L29: =SUMIF(管道站场阀室关系!B:B,支线管道!C29,管道站场阀室关系!J:J) -> 7513.8928 | N29: 东部
A30: 29 | B30: 江苏LNG外输管道 | C30: 江如管道 | D30: 江都分输站 | E30: 如东分输站 | F30: =SUMIF(管道站场阀室关系!B:B,支线管道!C30,管道站场阀室关系!H:H) -> 221.4 | G30: 1016 | H30: 21 | I30: 10 | J30: 135 | L30: =SUMIF(管道站场阀室关系!B:B,支线管道!C30,管道站场阀室关系!J:J) -> 164554.12 | M30: 201007江都-泰州 20110518泰州-如东 | N30: 东部
A31: 30 | B31: 江苏LNG外输管道 | C31: 如东-海门-崇明岛支线 | D31: 如东分输站 | E31: 崇明燃气门站 | F31: =SUMIF(管道站场阀室关系!B:B,支线管道!C31,管道站场阀室关系!H:H) -> 83.857 | G31: 610 | I31: 10/6.3 | L31: =SUMIF(管道站场阀室关系!B:B,支线管道!C31,管道站场阀室关系!J:J) -> 42374.008 | M31: 20170908 | N31: 东部
A32: 31 | B32: 江苏LNG外输管道 | C32: 泰芙联络线 | D32: 泰兴分输站 | E32: 芙蓉分输站 | F32: =SUMIF(管道站场阀室关系!B:B,支线管道!C32,管道站场阀室关系!H:H) -> 57.9 | G32: 1016 | H32: 26.2 | I32: 10 | J32: 62.5 | L32: =SUMIF(管道站场阀室关系!B:B,支线管道!C32,管道站场阀室关系!J:J) -> 42509.318 | M32: 20140915 | N32: 东部
A33: 32 | B33: 江苏LNG外输管道 | C33: 大唐如皋电厂支线 | D33: 如皋分输站 | E33: 大唐电厂末站 | F33: =SUMIF(管道站场阀室关系!B:B,支线管道!C33,管道站场阀室关系!H:H) -> 28.72 | G33: 219.1 | I33: 6.3 | J33: 2 | K33: 57 | L33: 902 | M33: 20250802 | N33: 东部
A34: 33 | B34: 淮武线 | C34: 淮武线 | D34: 淮阳压气站 | E34: 武汉西分输站 | F34: =SUMIF(管道站场阀室关系!B:B,支线管道!C34,管道站场阀室关系!H:H) -> 436.889 | G34: 610 | H34: 7 | I34: 6.3 | J34: 22 | L34: =SUMIF(管道站场阀室关系!B:B,支线管道!C34,管道站场阀室关系!J:J) -> 116059 | M34: 20061215 | N34: 东部
A35: 34 | B35: 西气东输二线 | C35: 西二线干线新疆段 | D35: 霍尔果斯压气站 | E35: 红柳压气站 | F35: =SUMIF(管道站场阀室关系!B:B,支线管道!C35,管道站场阀室关系!H:H) -> 1350.101 | G35: 1219 | H35: 27 | I35: 12 | J35: 300 | K35: 8571 | L35: =SUMIF(管道站场阀室关系!B:B,支线管道!C35,管道站场阀室关系!J:J) -> 1472005 | M35: 20091215 | N35: 西部
A36: 35 | B36: 西气东输二线 | C36: 西二线干线甘肃段 | D36: 红柳压气站 | E36: 中卫压气站 | F36: =SUMIF(管道站场阀室关系!B:B,支线管道!C36,管道站场阀室关系!H:H) -> 1076.2283 | G36: 1219 | H36: 27 | I36: 12 | J36: 300 | K36: 8571 | L36: =SUMIF(管道站场阀室关系!B:B,支线管道!C36,管道站场阀室关系!J:J) -> 1171905 | M36: 20091215 | N36: 西部
A37: 36 | B37: 西气东输二线 | C37: 西二线干线中卫-吉安段 | D37: 中卫压气站 | E37: 吉安分输站 | F37: =SUMIF(管道站场阀室关系!B:B,支线管道!C37,管道站场阀室关系!H:H) -> 1953.7728 | G37: 1219 | H37: 20 | I37: 10 | J37: 280 | K37: 8000 | L37: =SUMIF(管道站场阀室关系!B:B,支线管道!C37,管道站场阀室关系!J:J) -> 2151274.9 | M37: 中卫至黄陂20101118 黄陂至吉安20110620 | N37: 中部
A38: 37 | B38: 西气东输二线 | C38: 西二线干线吉安-广州段 | D38: 吉安分输站 | E38: 广州压气站 | F38: =SUMIF(管道站场阀室关系!B:B,支线管道!C38,管道站场阀室关系!H:H) -> 530.7142 | G38: 1219 | H38: 20 | I38: 10 | J38: 280 | K38: 8000 | L38: =SUMIF(管道站场阀室关系!B:B,支线管道!C38,管道站场阀室关系!J:J) -> 557972.76 | M38: 20110620 | N38: 南部
A39: 38 | B39: 西气东输二线 | C39: 独石化支线 | D39: 奎屯分输站 | E39: 独石化末站 | F39: =SUMIF(管道站场阀室关系!B:B,支线管道!C39,管道站场阀室关系!H:H) -> 8.1 | G39: 219 | H39: 7.1 | I39: 6.3 | J39: 6 | K39: 171 | L39: =SUMIF(管道站场阀室关系!B:B,支线管道!C39,管道站场阀室关系!J:J) -> 267 | M39: 201012 | N39: 西部
A40: 39 | B40: 西气东输二线 | C40: 嘉峪关支线 | D40: 嘉峪关压气站 | E40: 嘉峪关门站 | F40: =SUMIF(管道站场阀室关系!B:B,支线管道!C40,管道站场阀室关系!H:H) -> 15.14 | G40: 168 | H40: 5.6 | I40: 6.3 | J40: 2.4 | L40: =SUMIF(管道站场阀室关系!B:B,支线管道!C40,管道站场阀室关系!J:J) -> 292 | M40: 20110413 | N40: 西部 | O40: 河西五市供气支线
...

Sheet 管道站场阀室关系
A1: [关联]干线管道 | B1: [关联]支线管道 | C1: [原始]站场阀室 | D1: [计算]站场阀室 | E1: [原始]区域公司 | F1: [原始]作业区 | G1: [原始]里程,km | H1: [原始]站间距,km | I1: [原始]高程,m | J1: [原始]站间管容,方 | K1: [原始]累计管容,方 | L1: [原始]备注 | M1: [原始]支线管道简称 | N1: [原始]符号 ●跨接 ★监控阀室 ▲监视阀室 | O1: [原始]2024年类型 | P1: [原始]2025年类型 | Q1: [原始]地理位置
A2: 西气东输一线 | B2: 西一线干线新疆段 | C2: 轮南压气站 | D2: 轮南压气站● | E2: 西部管道 | F2: 轮南作业区 | G2: 0 | H2: 0 | I2: 930 | J2: 0 | K2: 0 | L2: 西一、轮吐合建 | M2: 西一 | N2: ● | O2: 压气站 | P2: 压气站 | Q2: 新疆维吾尔自治区巴音郭楞蒙古自治州轮台县轮南镇西南侧约1m
A3: 西气东输一线 | B3: 西一线干线新疆段 | C3: 西一1#阀室 | D3: 1#阀室★ | E3: 西部管道 | F3: 轮南作业区 | G3: 32.5005 | H3: =G3-G2 -> 32.5005 | I3: 924 | J3: 24800 | K3: 24800 | M3: 西一 | N3: ★ | O3: 监控阀室 | P3: 监控阀室 | Q3: 新疆维吾尔自治区巴音郭楞蒙古自治州轮台县阿克萨来乡
A4: 西气东输一线 | B4: 西一线干线新疆段 | C4: 西一2#阀室 | D4: 2#阀室★ | E4: 西部管道 | F4: 轮南作业区 | G4: 62.5294 | H4: =G4-G3 -> 30.0289 | I4: 910 | J4: 22914 | K4: 47714 | M4: 西一 | N4: ★ | O4: 监控阀室 | P4: 监控阀室 | Q4: 新疆维吾尔自治区巴音郭楞蒙古自治州轮台县
A5: 西气东输一线 | B5: 西一线干线新疆段 | C5: 西一3#阀室 | D5: 3#阀室★ | E5: 西部管道 | F5: 轮南作业区 | G5: 95.5411 | H5: =G5-G4 -> 33.0117 | I5: 901 | J5: 25190 | K5: 72904 | M5: 西一 | N5: ★ | O5: 监控阀室 | P5: 监控阀室 | Q5: 新疆维吾尔自治区巴音郭楞蒙古自治州轮台县
A6: 西气东输一线 | B6: 西一线干线新疆段 | C6: 西一4#阀室 | D6: 4#阀室★ | E6: 西部管道 | F6: 库尔勒作业区 | G6: 128.5829 | H6: =G6-G5 -> 33.0418 | I6: 925 | J6: 25213 | K6: 98117 | M6: 西一 | N6: ★ | O6: 监控阀室 | P6: 监控阀室 | Q6: 新疆维吾尔自治区巴音郭楞蒙古自治州库尔勒市
A7: 西气东输一线 | B7: 西一线干线新疆段 | C7: 西一5#阀室 | D7: 5#阀室★ | E7: 西部管道 | F7: 库尔勒作业区 | G7: 159.4256 | H7: =G7-G6 -> 30.8427 | I7: 983 | J7: 23535 | K7: 121652 | M7: 西一 | N7: ★ | O7: 监控阀室 | P7: 监控阀室 | Q7: 新疆维吾尔自治区巴音郭楞蒙古自治州库尔勒市上户镇
A8: 西气东输一线 | B8: 西一线干线新疆段 | C8: 孔雀河压气站 | D8: 孔雀河压气站● | E8: 西部管道 | F8: 库尔勒作业区 | G8: 178.5865 | H8: =G8-G7 -> 19.1609 | I8: 1078 | J8: 16070 | K8: 137722 | L8: 西一、轮吐合建、连通 | M8: 西一 | N8: ● | O8: 压气站 | P8: 压气站 | Q8: 新疆维吾尔自治区巴音郭楞蒙古自治州库尔勒市新城街道
A9: 西气东输一线 | B9: 西一线干线新疆段 | C9: 西一6#阀室 | D9: 6#阀室★ | E9: 西部管道 | F9: 库尔勒作业区 | G9: 205.8962 | H9: =G9-G8 -> 27.3097 | I9: 1091 | J9: 20839 | K9: 158561 | M9: 西一 | N9: ★ | O9: 监控阀室 | P9: 监控阀室 | Q9: 新疆维吾尔自治区巴音郭楞蒙古自治州博湖县博斯腾湖乡西南侧约25km
A10: 西气东输一线 | B10: 西一线干线新疆段 | C10: 西一7#阀室 | D10: 7#阀室★ | E10: 西部管道 | F10: 库尔勒作业区 | G10: 231.7165 | H10: =G10-G9 -> 25.8203 | I10: 1082 | J10: 19702 | K10: 178263 | M10: 西一 | N10: ★ | O10: 监控阀室 | P10: 监控阀室 | Q10: 新疆维吾尔自治区巴音郭楞蒙古自治州博湖县博斯腾湖乡东侧约6km
A11: 西气东输一线 | B11: 西一线干线新疆段 | C11: 西一8#阀室 | D11: 8#阀室★ | E11: 西部管道 | F11: 库尔勒作业区 | G11: 258.4479 | H11: =G11-G10 -> 26.7314 | I11: 1099 | J11: 20398 | K11: 198661 | M11: 西一 | N11: ★ | O11: 监控阀室 | P11: 监控阀室 | Q11: 新疆维吾尔自治区巴音郭楞蒙古自治州博湖县博斯腾湖乡东侧约38km
A12: 西气东输一线 | B12: 西一线干线新疆段 | C12: 西一9#阀室 | D12: 9#阀室★ | E12: 西部管道 | F12: 马兰作业区 | G12: 283.6799 | H12: =G12-G11 -> 25.232 | I12: 1051 | J12: 19253 | K12: 217914 | M12: 西一 | N12: ★ | O12: 监控阀室 | P12: 监控阀室 | Q12: 新疆维吾尔自治区巴音郭楞蒙古自治州和硕县乌什塔拉乡南侧6km
A13: 西气东输一线 | B13: 西一线干线新疆段 | C13: 四道班压气站 | D13: 四道班压气站 | E13: 西部管道 | F13: 马兰作业区 | G13: 315.9608 | H13: =G13-G12 -> 32.2809 | I13: 1164 | J13: 23664 | K13: 241578 | M13: 西一 | O13: 压气站 | P13: 压气站 | Q13: 新疆维吾尔自治区巴音郭楞蒙古自治州和硕县乌什塔拉乡南侧65km
A14: 西气东输一线 | B14: 西一线干线新疆段 | C14: 西一10#阀室 | D14: 10#阀室★ | E14: 西部管道 | F14: 库米什压气站 | G14: 347.4971 | H14: =G14-G13 -> 31.5363 | I14: 1336 | J14: 24064 | K14: 265642 | L14: 5#阀室 | M14: 西一 | N14: ★ | O14: 监控阀室 | P14: 监控阀室 | Q14: 新疆维吾尔自治区吐鲁番市托克逊县库米什镇
A15: 西气东输一线 | B15: 西一线干线新疆段 | C15: 西一11#阀室 | D15: 11#阀室★ | E15: 西部管道 | F15: 库米什压气站 | G15: 378.0201 | H15: =G15-G14 -> 30.523 | I15: 914 | J15: 23291 | K15: 288933 | M15: 西一 | N15: ★ | O15: 监控阀室 | P15: 监控阀室 | Q15: 新疆维吾尔自治区吐鲁番市托克逊县库米什镇西南侧43km
A16: 西气东输一线 | B16: 西一线干线新疆段 | C16: 西一11A#阀室 | D16: 11A#阀室★ | E16: 西部管道 | F16: 库米什压气站 | G16: 398.0201 | H16: =G16-G15 -> 20 | I16: - | J16: - | K16: - | M16: 西一 | N16: ★ | O16: 监控阀室 | P16: 监控阀室 | Q16: 新疆维吾尔自治区吐鲁番地区托克逊县
A17: 西气东输一线 | B17: 西一线干线新疆段 | C17: 西一12#阀室 | D17: 12#阀室★ | E17: 西部管道 | F17: 库米什压气站 | G17: 405.859 | H17: =G17-G16 -> 7.8389 | I17: 1352 | J17: 21243 | K17: 310176 | M17: 西一 | N17: ★ | O17: 监控阀室 | P17: 监控阀室 | Q17: 新疆维吾尔自治区吐鲁番市托克逊县库米什镇
A18: 西气东输一线 | B18: 西一线干线新疆段 | C18: 西一13#阀室 | D18: 13#阀室★ | E18: 西部管道 | F18: 库米什压气站 | G18: 435.7706 | H18: =G18-G17 -> 29.9116 | I18: 1363 | J18: 22824 | K18: 333000 | M18: 西一 | N18: ★ | O18: 监控阀室 | P18: 监控阀室 | Q18: 新疆维吾尔自治区吐鲁番市鄯善县迪坎乡
A19: 西气东输一线 | B19: 西一线干线新疆段 | C19: 西一14#阀室 | D19: 14#阀室★ | E19: 西部管道 | F19: 库米什压气站 | G19: 466.1453 | H19: =G19-G18 -> 30.3747 | I19: 960 | J19: 23178 | K19: 356178 | M19: 西一 | N19: ★ | O19: 监控阀室 | P19: 监控阀室 | Q19: 新疆维吾尔自治区吐鲁番市鄯善县迪坎乡
A20: 西气东输一线 | B20: 西一线干线新疆段 | C20: 鄯善压气站 | D20: 鄯善压气站 | E20: 西部管道 | F20: 库米什压气站 | G20: 494.5473 | H20: =G20-G19 -> 28.402 | I20: 815 | J20: 23672 | K20: 379850 | M20: 西一 | O20: 压气站 | P20: 压气站 | Q20: 新疆维吾尔自治区吐鲁番市鄯善县迪坎乡
A21: 西气东输一线 | B21: 西一线干线新疆段 | C21: 西一15#阀室 | D21: 15#阀室★ | E21: 西部管道 | F21: 库米什压气站 | G21: 525.2838 | H21: =G21-G20 -> 30.7365 | I21: 883 | J21: 23454 | K21: 403304 | M21: 西一 | N21: ★ | O21: 监控阀室 | P21: 监控阀室 | Q21: 新疆维吾尔自治区吐鲁番市鄯善县迪坎乡
A22: 西气东输一线 | B22: 西一线干线新疆段 | C22: 西一16#阀室 | D22: 16#阀室★ | E22: 西部管道 | F22: 库米什压气站 | G22: 552.4161 | H22: =G22-G21 -> 27.1323 | I22: 942 | J22: 20704 | K22: 424008 | M22: 西一 | N22: ★ | O22: 监控阀室 | P22: 监控阀室 | Q22: 新疆维吾尔自治区吐鲁番市鄯善县迪坎乡
A23: 西气东输一线 | B23: 西一线干线新疆段 | C23: 西一17#阀室 | D23: 17#阀室★ | E23: 西部管道 | F23: 库米什压气站 | G23: 583.6908 | H23: =G23-G22 -> 31.2747 | I23: 1040 | J23: 23864 | K23: 447872 | M23: 西一 | N23: ★ | O23: 监控阀室 | P23: 监控阀室 | Q23: 新疆维吾尔自治区吐鲁番市鄯善县迪坎乡
A24: 西气东输一线 | B24: 西一线干线新疆段 | C24: 西一18#阀室 | D24: 18#阀室★ | E24: 西部管道 | F24: 哈密压气站 | G24: 614.4744 | H24: =G24-G23 -> 30.7836 | I24: 1045 | J24: 23490 | K24: 471362 | M24: 西一 | N24: ★ | O24: 监控阀室 | P24: 监控阀室 | Q24: 新疆维吾尔自治区吐鲁番市鄯善县迪坎乡
A25: 西气东输一线 | B25: 西一线干线新疆段 | C25: 西一19#阀室 | D25: 19#阀室★ | E25: 西部管道 | F25: 哈密压气站 | G25: 645.242 | H25: =G25-G24 -> 30.7676 | I25: 1017 | J25: 23477 | K25: 494839 | M25: 西一 | N25: ★ | O25: 监控阀室 | P25: 监控阀室 | Q25: 新疆维吾尔自治区吐鲁番市鄯善县迪坎乡
A26: 西气东输一线 | B26: 西一线干线新疆段 | C26: 哈密压气站 | D26: 哈密压气站 | E26: 西部管道 | F26: 哈密压气站 | G26: 659.3964 | H26: =G26-G25 -> 14.1544 | I26: 1070 | J26: 13235 | K26: 508074 | M26: 西一 | O26: 压气站 | P26: 压气站 | Q26: 新疆维吾尔自治区吐鲁番市鄯善县迪坎乡
A27: 西气东输一线 | B27: 西一线干线新疆段 | C27: 西一20#阀室 | D27: 20#阀室★ | E27: 西部管道 | F27: 哈密压气站 | G27: 688.8259 | H27: =G27-G26 -> 29.4295 | I27: 1083 | J27: 22456 | K27: 530530 | M27: 西一 | N27: ★ | O27: 监控阀室 | P27: 监控阀室 | Q27: 新疆维吾尔自治区吐鲁番市鄯善县迪坎乡
A28: 西气东输一线 | B28: 西一线干线新疆段 | C28: 西一21#阀室 | D28: 21#阀室★ | E28: 西部管道 | F28: 哈密压气站 | G28: 718.7445 | H28: =G28-G27 -> 29.9186 | I28: 951 | J28: 22830 | K28: 553360 | M28: 西一 | N28: ★ | O28: 监控阀室 | P28: 监控阀室 | Q28: 新疆维吾尔自治区吐鲁番市鄯善县迪坎乡
A29: 西气东输一线 | B29: 西一线干线新疆段 | C29: 西一22#阀室 | D29: 22#阀室★ | E29: 西部管道 | F29: 哈密压气站 | G29: 760.9221 | H29: =G29-G28 -> 42.1776 | I29: 979 | J29: 32184 | K29: 585544 | M29: 西一 | N29: ★ | O29: 监控阀室 | P29: 监控阀室 | Q29: 新疆维吾尔自治区哈密市伊州区大南湖乡
A30: 西气东输一线 | B30: 西一线干线新疆段 | C30: 西一23#阀室 | D30: 23#阀室★ | E30: 西部管道 | F30: 哈密压气站 | G30: 793.3765 | H30: =G30-G29 -> 32.4544 | I30: 1035 | J30: 24765 | K30: 610309 | M30: 西一 | N30: ★ | O30: 监控阀室 | P30: 监控阀室 | Q30: 新疆维吾尔自治区哈密市伊州区大南湖乡
A31: 西气东输一线 | B31: 西一线干线新疆段 | C31: 雅满苏压气站 | D31: 雅满苏压气站 | E31: 西部管道 | F31: 雅满苏压气站 | G31: 824.2455 | H31: =G31-G30 -> 30.869 | I31: 969 | J31: 21996 | K31: 632305 | M31: 西一 | O31: 压气站 | P31: 压气站 | Q31: 新疆维吾尔自治区哈密市伊州区雅满苏镇
A32: 西气东输一线 | B32: 西一线干线新疆段 | C32: 西一25#阀室 | D32: 25#阀室★ | E32: 西部管道 | F32: 雅满苏压气站 | G32: 860.244 | H32: =G32-G31 -> 35.9985 | I32: 1028 | J32: 27469 | K32: 659774 | M32: 西一 | N32: ★ | O32: 监控阀室 | P32: 监控阀室 | Q32: 新疆维吾尔自治区哈密市伊州区雅满苏镇
A33: 西气东输一线 | B33: 西一线干线新疆段 | C33: 西一26#阀室 | D33: 26#阀室★ | E33: 西部管道 | F33: 雅满苏压气站 | G33: 892.2669 | H33: =G33-G32 -> 32.0229 | I33: 1046 | J33: 4058 | K33: 663832 | M33: 西一 | N33: ★ | O33: 监控阀室 | P33: 监控阀室 | Q33: 新疆维吾尔自治区哈密市伊州区雅满苏镇
A34: 西气东输一线 | B34: 西一线干线新疆段 | C34: 西一27#阀室 | D34: 27#阀室★ | E34: 西部管道 | F34: 雅满苏压气站 | G34: 923.5386 | H34: =G34-G33 -> 31.2717 | I34: 1297 | J34: 23862 | K34: 687694 | M34: 西一 | N34: ★ | O34: 监控阀室 | P34: 监控阀室 | Q34: 新疆维吾尔自治区哈密市伊州区雅满苏镇
A35: 西气东输一线 | B35: 西一线干线新疆段 | C35: 西一28#阀室 | D35: 28#阀室★ | E35: 西部管道 | F35: 烟墩作业区 | G35: 954.9577 | H35: =G35-G34 -> 31.4191 | I35: 1530 | J35: 23975 | K35: 711669 | M35: 西一 | N35: ★ | O35: 监控阀室 | P35: 监控阀室 | Q35: 新疆维吾尔自治区哈密市伊州区星星峡镇
A36: 西气东输一线 | B36: 西一线干线甘肃段 | C36: 红柳压气站 | D36: 红柳压气站● | E36: 甘肃公司 | F36: 红柳作业区 | G36: 961.6198 | H36: =G36-G35 -> 6.6621 | I36: 1627 | J36: 23779 | K36: 735448 | L36: 西一、西二、西三合建、连通 | M36: 西一 | N36: ● | O36: 压气站 | P36: 压气站 | Q36: 甘肃省酒泉市安西县柳园镇安西极旱荒漠自然保护区
A37: 西气东输一线 | B37: 西一线干线甘肃段 | C37: 西一29#阀室 | D37: 29#阀室★ | E37: 甘肃公司 | F37: 红柳作业区 | G37: 995.5445 | H37: =G37-G36 -> 33.9247 | I37: 1770 | J37: 25913 | K37: 761361 | M37: 西一 | N37: ★ | O37: 监控阀室 | P37: 监控阀室 | Q37: 甘肃省酒泉市安西县柳园镇安西极旱荒漠自然保护区
A38: 西气东输一线 | B38: 西一线干线甘肃段 | C38: 西一30#阀室 | D38: 30#阀室★ | E38: 甘肃公司 | F38: 红柳作业区 | G38: 1025.5133 | H38: =G38-G37 -> 29.9688 | I38: 1768 | J38: 22892 | K38: 784253 | M38: 西一 | N38: ★ | O38: 监控阀室 | P38: 监控阀室 | Q38: 甘肃省酒泉市安西县柳园镇戈壁滩
A39: 西气东输一线 | B39: 西一线干线甘肃段 | C39: 西一31#阀室 | D39: 31#阀室★ | E39: 甘肃公司 | F39: 红柳作业区 | G39: 1057.029 | H39: =G39-G38 -> 31.5157 | I39: 1649 | J39: 24073 | K39: 808326 | M39: 西一 | N39: ★ | O39: 监控阀室 | P39: 监控阀室 | Q39: 甘肃省酒泉市安西县柳园镇戈壁滩
A40: 西气东输一线 | B40: 西一线干线甘肃段 | C40: 西一32#阀室 | D40: 32#阀室★ | E40: 甘肃公司 | F40: 瓜州作业区 | G40: 1087.6116 | H40: =G40-G39 -> 30.5826 | I40: 1539 | J40: 23360 | K40: 831686 | M40: 西一 | N40: ★ | O40: 监控阀室 | P40: 监控阀室 | Q40: 甘肃省酒泉市瓜州县戈壁滩
...

Sheet 分输口
A1: [关联] 干线管道 | B1: [原始] 分输口 | C1: [原始] 自动分输 | D1: [原始]站场/阀室/干线开口 | E1: [关联]站场简称 | F1: 备注 | G1: [关联]调度台 | H1: 站场计量设备情况 | I1: 站场调压设备情况 | J1: 用户合同接气压力 MPa | K1: 投产时间
A2: 西气东输二线 | B2: 新捷伊犁<伊宁> | C2: 五期 | D2: 站场 | E2: 伊宁首 | G2: 西部 | H2: 1用1备 | I2: 1用1备 | J2: 3.8-10
A3: 西气东输二线 | B3: 新捷伊犁<霍尔果斯> | C3: 二期 | D3: 站场 | E3: 霍尔果斯 | G3: 西部 | H3: 1用1备 | I3: 1用1备 | J3: 干线压力
A4: 西气东输二线 | B4: 兵团燃气（喀什）<霍尔果斯> | C4: 二期 | D4: 站场 | E4: 霍尔果斯 | G4: 西部 | H4: 1用1备 | I4: 1用1备 | J4: 干线压力
A5: 西气东输二线 | B5: 新捷博乐<精河> | C5: 二期 | D5: 站场 | E5: 精河 | G5: 西部 | H5: 1用1备 | I5: 1用1备 | J5: 干线压力
A6: 西气东输二线 | B6: 新捷博乐<西二9#> | C6: 2024年已报 | D6: 阀室 | E6: 西二9# | G6: 西部 | J6: 5.5-11.0
A7: 西气东输二线 | B7: 乌苏宏江<乌苏> | C7: 三期 | D7: 站场 | E7: 乌苏 | G7: 西部 | H7: 1用1备 | J7: 干线压力
A8: 西气东输二线 | B8: 玛纳斯新捷<玛纳斯> | C8: 二期 | D8: 站场 | E8: 玛纳斯 | G8: 西部 | H8: 1用1备 | I8: 1用1备 | J8: 干线压力
A9: 西气东输三线 | B9: 天富天源（西三线）<石河子> | C9: 二期 | D9: 站场 | E9: 石河子 | G9: 西部 | H9: 1用1备 | I9: 1用1备 | J9: 干线压力
A10: 西气东输二线 | B10: 独山子石化(西二线)<奎屯> | C10: 二期 | D10: 站场 | E10: 奎屯 | G10: 西部 | H10: 1用1备 | I10: 1用1备 | J10: 干线压力
A11: 西气东输二线 | B11: 奎屯德信<奎屯> | C11: 二期 | D11: 站场 | E11: 奎屯 | G11: 西部 | H11: 1用1备 | I11: 1用1备 | J11: 干线压力
A12: 西气东输二线 | B12: 奎屯非创<奎屯> | C12: 二期 | D12: 站场 | E12: 奎屯 | G12: 西部 | H12: 1用1备 | I12: 1用1备 | J12: 干线压力
A13: 西气东输二线 | B13: 奎屯新捷<奎屯> | C13: 四期 | D13: 站场 | E13: 奎屯 | G13: 西部 | H13: 1用1备 | I13: 1用1备 | J13: 干线压力
A14: 西气东输二线 | B14: 沙湾东升<西二14#> | C14: 四期 | D14: 阀室 | E14: 西二14# | G14: 西部 | H14: 1用1备 | I14: 1用1备 | J14: 干线压力
A15: 西气东输二线 | B15: 鑫泰燃气公司(米泉)<乌石化> | C15: 一期 | D15: 站场 | E15: 乌石化 | G15: 西部 | H15: 1用1备 | I15: 1用1备 | J15: 干线压力
A16: 西气东输二线 | B16: 新疆油田<乌石化> | C16: 一期 | D16: 站场 | E16: 乌石化 | G16: 西部 | H16: 无 | I16: 1用1备 | J16: 4.5-9.0
A17: 西气东输二线 | B17: 乌石化(西二线)<乌石化> | C17: 一期 | D17: 站场 | E17: 乌石化 | G17: 西部 | H17: 1用1备 | I17: 1用1备 | J17: 干线压力
A18: 西气东输二线 | B18: 新捷燃气<西二19#> | C18: 2024年已报 | D18: 阀室 | E18: 西二19# | G18: 西部 | H18: 2用1备 | I18: 1用1备 | J18: 7-11.6
A19: 西气东输二线 | B19: 昊通百圣<昌吉> | C19: 二期 | D19: 站场 | E19: 昌吉 | G19: 西部 | H19: 1用1备 | I19: 1用1备 | J19: 7.0-11.5
... A25: 西气东输二线 | B25: 新捷燃气<乌鲁木齐> | C25: 一期 | D25: 站场 | E25: 乌鲁木齐 | G25: 西部 | H25: 1用1备 | I25: 1用1备 | J25: 干线压力
A26: 西气东输二线 | B26: 巴州洪通<孔雀河> | D26: 站场 | E26: 孔雀河 | G26: 西部 | H26: 2用1备 | I26: 2用1备 | J26: 2.5-9.0 | K26: 2024.3
A27: 西气东输二线 | B27: 昆仑燃气巴州分公司<孔雀河> | C27: 2025已投 | D27: 站场 | E27: 孔雀河 | G27: 西部 | H27: 1用1备 | I27: 1用1备 | J27: 2.5-9 | K27: 45929
A28: 西气东输二线 | B28: 国泰鸿远<轮吐6#> | C28: 二期 | D28: 阀室 | E28: 轮吐6# | G28: 西部 | H28: 1用1备 | I28: 1用1备 | J28: 干线压力
A29: 西气东输二线 | B29: 吐鲁番新捷<库米什> | D29: 站场 | E29: 库米什 | G29: 西部 | H29: 1用1备 | I29: 1用1备 | J29: 2.5-10.0 | K29: 2024.2
A30: 西气东输二线 | B30: 托克逊新捷<轮吐14#> | C30: 二期 | D30: 阀室 | E30: 轮吐14# | G30: 西部 | H30: 1用1备 | I30: 1用1备 | J30: 干线压力
A31: 西气东输二线 | B31: 哈密新捷<哈密>A | C31: 二期 | D31: 站场 | E31: 哈密 | G31: 西部 | H31: 1用1备 | I31: 1用1备 | J31: 5.8
A32: 西气东输二线 | B32: 哈密新捷<哈密>B | C32: 2024年已报 | D32: 站场 | E32: 哈密 | G32: 西部 | J32: 5.0-12.0
A33: 西气东输二线 | B33: 哈密洪通<哈密> | C33: 2024年已报 | D33: 站场 | E33: 哈密 | G33: 西部 | J33: 5.0-10.0
A34: 西气东输一线 | B34: 瓜州昆仑<瓜州> | C34: 2024年已报 | D34: 站场 | E34: 瓜州 | G34: 西部 | J34: 4-10
A35: 西气东输二线 | B35: 嘉峪关昆仑<嘉峪关> | C35: 二期 | D35: 站场 | E35: 嘉峪关 | G35: 西部 | H35: 1用1备 | I35: 1用1备 | J35: 干线压力
A36: 西气东输二线 | B36: 酒泉昆仑<嘉峪关> | C36: 二期 | D36: 站场 | E36: 嘉峪关 | G36: 西部 | H36: 1用1备 | I36: 1用1备 | J36: 干线压力
A37: 西气东输二线 | B37: 嘉峪关昆仑(新)<嘉峪关> | C37: 2024已投 | D37: 站场 | E37: 嘉峪关 | G37: 西部 | H37: 两用一备 | I37: 1用1备 | J37: 0.5-6.3 | K37: 2024.5
A38: 西气东输二线 | B38: 张掖中油<张掖> | C38: 四期 | D38: 站场 | E38: 张掖 | G38: 西部 | H38: 1用1备 | I38: 1用1备 | J38: 干线压力
A39: 西气东输二线 | B39: 张掖昆仑<张掖> | C39: 二期 | D39: 站场 | E39: 张掖 | G39: 西部 | H39: 1用1备 | I39: 1用1备 | J39: 干线压力
A40: 西气东输二线 | B40: 丰聚能源<西二57#> | C40: 四期 | D40: 阀室 | E40: 西二57# | G40: 西部 | H40: 2用2备 | I40: 1用1备 | J40: 干线压力
A41: 西气东输二线 | B41: 甘肃浩源<金昌> | C41: 二期 | D41: 站场 | E41: 金昌 | G41: 西部 | H41: 1用1备 | I41: 1用1备 | J41: 干线压力
A42: 西气东输二线 | B42: 金昌昆仑<金昌> | C42: 二期 | D42: 站场 | E42: 金昌 | G42: 西部 | H42: 1用1备 | I42: 1用1备 | J42: 干线压力
A43: 西气东输二线 | B43: 武威昆仑<武威> | C43: 二期 | D43: 站场 | E43: 武威 | G43: 西部 | H43: 1用1备 | I43: 1用1备 | J43: 干线压力
A44: 西气东输二线 | B44: 时代燃气<霍尔果斯> | C44: 2024已投 | D44: 站场 | E44: 霍尔果斯 | G44: 西部 | H44: 2台流量计，FT112011、FT112021 | I44: 等压 | J44: 6-11.5 | K44: 2024.10
A45: 西气东输二线 | B45: 华海电厂<德庆> | C45: 2024已投 | D45: 站场 | E45: 德庆 | G45: 南部 | H45: 1用1备 | I45: 1用1备 | J45: 4 | K45: 2024.12
...

Sheet 调度台
A1: [原始]序号 | B1: [原始]调度台
A2: 1 | B2: 西部
A3: 2 | B3: 北部
A4: 3 | B4: 中部
A5: 4 | B5: 东部
A6: 5 | B6: 南部
A7: 6 | B7: 省网

Sheet 压缩机
A1: [原始]地区公司 | B1: [计算]调控级别 | C1: [计算]干线管道 | D1: [计算]支线管道 | E1: [关联]站场 | F1: [原始]机组配置 | G1: [原始]压缩机组编号 | H1: [原始]72h测试完成时间 | I1: [原始]驱动方式 | J1: [原始]进口/国产 | K1: [原始]压缩机厂商 | L1: [原始]压缩机型号 | M1: [原始]驱动机型号及 制造商 | N1: [原始]连续运行工作转速范围rpm | O1: [原始]最大连续运行转速rpm | P1: [原始]入口压力范围MPa | Q1: [原始]驱动机额定功率MW | R1: [原始]机组投产情况 | S1: [原始]余热利用 | T1: 压缩机平台 | U1: [原始]备注
A2: 西部管道 | B2: =VLOOKUP(C2,[1]干线管道!B:C,2,FALSE) -> 一级 | C2: =VLOOKUP(E2,[1]站场阀室!A:D,3,FALSE) -> 西气东输一线 | D2: 西一线干线新疆段 | E2: 轮南压气站 | F2: 2+1 | G2: 1# | H2: 38231 | I2: 燃驱 | J2: 进口 | K2: Rolls-Royce | L2: RF2BB36 | M2: RB211-24G/RR | N2: 3120-4800 | O2: 5040 | P2: >5 | Q2: 29.53 | R2: 投产 | S2: 无 | T2: 一期
A3: 西部管道 | B3: =VLOOKUP(C3,[1]干线管道!B:C,2,FALSE) -> 一级 | C3: =VLOOKUP(E3,[1]站场阀室!A:D,3,FALSE) -> 西气东输一线 | D3: 西一线干线新疆段 | E3: 轮南压气站 | F3: 2+1 | G3: 2# | H3: 38231 | I3: 燃驱 | J3: 进口 | K3: Rolls-Royce | L3: RF2BB36 | M3: RB211-24G/RR | N3: 3120-4800 | O3: 5040 | P3: >5 | Q3: 29.53 | R3: 投产 | T3: 一期
A4: 西部管道 | B4: =VLOOKUP(C4,[1]干线管道!B:C,2,FALSE) -> 一级 | C4: =VLOOKUP(E4,[1]站场阀室!A:D,3,FALSE) -> 西气东输一线 | D4: 西一线干线新疆段 | E4: 轮南压气站 | F4: 2+1 | G4: 3# | H4: 40126 | I4: 燃驱 | J4: 进口 | K4: Rolls-Royce | L4: RF2BB36 | M4: RB211-24G/RR | N4: 3120-4800 | O4: 5040 | P4: >5 | Q4: 29.53 | R4: 投产 | T4: 一期
A5: 西部管道 | B5: =VLOOKUP(C5,[1]干线管道!B:C,2,FALSE) -> 一级 | C5: =VLOOKUP(E5,[1]站场阀室!A:D,3,FALSE) -> 西气东输一线 | D5: 西一线干线新疆段 | E5: 孔雀河压气站 | F5: 2+1 | G5: 1# | H5: 39080 | I5: 燃驱 | J5: 进口 | K5: General Electric | L5: PCL804 | M5: PGT25+SAC/GE | N5: 3965-6100 | O5: 6405 | P5: >3.8 | Q5: 31.4 | R5: 投产 | S5: 无 | T5: 一期
A6: 西部管道 | B6: =VLOOKUP(C6,[1]干线管道!B:C,2,FALSE) -> 一级 | C6: =VLOOKUP(E6,[1]站场阀室!A:D,3,FALSE) -> 西气东输一线 | D6: 西一线干线新疆段 | E6: 孔雀河压气站 | F6: 2+1 | G6: 2# | H6: 39117 | I6: 燃驱 | J6: 进口 | K6: General Electric | L6: PCL804 | M6: PGT25+SAC/GE | N6: 3965-6100 | O6: 6405 | P6: >3.8 | Q6: 31.4 | R6: 投产 | T6: 一期
A7: 西部管道 | B7: =VLOOKUP(C7,[1]干线管道!B:C,2,FALSE) -> 一级 | C7: =VLOOKUP(E7,[1]站场阀室!A:D,3,FALSE) -> 西气东输一线 | D7: 西一线干线新疆段 | E7: 孔雀河压气站 | F7: 2+1 | G7: 3# | H7: 40483 | I7: 燃驱 | J7: 进口 | K7: General Electric | L7: PCL804 | M7: PGT25+SAC/GE | N7: 3965-6100 | O7: 6405 | P7: >3.8 | Q7: 31.4 | R7: 投产 | T7: 一期
A8: 西部管道 | B8: =VLOOKUP(C8,[1]干线管道!B:C,2,FALSE) -> 一级 | C8: =VLOOKUP(E8,[1]站场阀室!A:D,3,FALSE) -> 西气东输一线 | D8: 西一线干线新疆段 | E8: 四道班压气站 | F8: 1+1 | G8: 1# | H8: 39071 | I8: 燃驱 | J8: 进口 | K8: Rolls-Royce | L8: RF2BB36 | M8: RB211-24G/RR | N8: 3120-4800 | O8: 5040 | P8: 报警值4，停机值3 | Q8: 29.53 | R8: 投产 | S8: 无 | T8: 一期
A9: 西部管道 | B9: =VLOOKUP(C9,[1]干线管道!B:C,2,FALSE) -> 一级 | C9: =VLOOKUP(E9,[1]站场阀室!A:D,3,FALSE) -> 西气东输一线 | D9: 西一线干线新疆段 | E9: 四道班压气站 | F9: 1+1 | G9: 2# | H9: 38248 | I9: 燃驱 | J9: 进口 | K9: Rolls-Royce | L9: RF2BB36 | M9: RB211-24G/RR | N9: 3120-4800 | O9: 5040 | P9: 报警值4，停机值3 | Q9: 29.53 | R9: 投产 | T9: 一期
A10: 西部管道 | B10: =VLOOKUP(C10,[1]干线管道!B:C,2,FALSE) -> 一级 | C10: =VLOOKUP(E10,[1]站场阀室!A:D,3,FALSE) -> 西气东输一线 | D10: 西一线干线新疆段 | E10: 鄯善压气站 | F10: 2+1 | G10: 1# | H10: 39122 | I10: 燃驱 | J10: 进口 | K10: General Electric | L10: PCL804 | M10: PGT25+SAC/GE | N10: 3965-6100 | O10: 6405 | P10: >5.8 | Q10: 31.364 | R10: 投产 | S10: 无 | T10: 一期
A11: 西部管道 | B11: =VLOOKUP(C11,[1]干线管道!B:C,2,FALSE) -> 一级 | C11: =VLOOKUP(E11,[1]站场阀室!A:D,3,FALSE) -> 西气东输一线 | D11: 西一线干线新疆段 | E11: 鄯善压气站 | F11: 2+1 | G11: 2# | H11: 39078 | I11: 燃驱 | J11: 进口 | K11: General Electric | L11: PCL804 | M11: PGT25+SAC/GE | N11: 3965-6100 | O11: 6405 | P11: >5.8 | Q11: 31.364 | R11: 投产 | T11: 一期
A12: 西部管道 | B12: =VLOOKUP(C12,[1]干线管道!B:C,2,FALSE) -> 一级 | C12: =VLOOKUP(E12,[1]站场阀室!A:D,3,FALSE) -> 西气东输一线 | D12: 西一线干线新疆段 | E12: 鄯善压气站 | F12: 2+1 | G12: 3# | H12: 40544 | I12: 燃驱 | J12: 进口 | K12: General Electric | L12: PCL804 | M12: PGT25+SAC/GE | N12: 3965-6100 | O12: 6405 | P12: >5.8 | Q12: 31.364 | R12: 投产 | T12: 一期
A13: 西部管道 | B13: =VLOOKUP(C13,[1]干线管道!B:C,2,FALSE) -> 一级 | C13: =VLOOKUP(E13,[1]站场阀室!A:D,3,FALSE) -> 西气东输一线 | D13: 西一线干线新疆段 | E13: 哈密压气站 | F13: 2+1 | G13: 1# | H13: 38658 | I13: 燃驱 | J13: 进口 | K13: Rolls-Royce | L13: RF3BB36 | M13: RB211-24G/RR | N13: 3120-4800 | O13: 5040 | P13: >4 | Q13: 29.53 | R13: 投产 | S13: 无 | T13: 一期
A14: 西部管道 | B14: =VLOOKUP(C14,[1]干线管道!B:C,2,FALSE) -> 一级 | C14: =VLOOKUP(E14,[1]站场阀室!A:D,3,FALSE) -> 西气东输一线 | D14: 西一线干线新疆段 | E14: 哈密压气站 | F14: 2+1 | G14: 2# | H14: 38695 | I14: 燃驱 | J14: 进口 | K14: Rolls-Royce | L14: RF3BB36 | M14: RB211-24G/RR | N14: 3120-4800 | O14: 5040 | P14: >4 | Q14: 29.53 | R14: 投产 | T14: 一期
A15: 西部管道 | B15: =VLOOKUP(C15,[1]干线管道!B:C,2,FALSE) -> 一级 | C15: =VLOOKUP(E15,[1]站场阀室!A:D,3,FALSE) -> 西气东输一线 | D15: 西一线干线新疆段 | E15: 哈密压气站 | F15: 2+1 | G15: 3# | H15: 40505 | I15: 燃驱 | J15: 进口 | K15: Rolls-Royce | L15: RF3BB36 | M15: RB211-24G/RR | N15: 3120-4800 | O15: 5040 | P15: >4 | Q15: 29.53 | R15: 投产 | T15: 一期
A16: 西部管道 | B16: =VLOOKUP(C16,[1]干线管道!B:C,2,FALSE) -> 一级 | C16: =VLOOKUP(E16,[1]站场阀室!A:D,3,FALSE) -> 西气东输一线 | D16: 西一线干线新疆段 | E16: 雅满苏压气站 | F16: 1+1 | G16: 1# | H16: 39351 | I16: 燃驱 | J16: 进口 | K16: General Electric | L16: PCL804 | M16: PGT25+SAC/GE | N16: 3965-6100 | O16: 6405 | P16: >5.8 | Q16: 31.364 | R16: 投产 | S16: 无 | T16: 一期
A17: 西部管道 | B17: =VLOOKUP(C17,[1]干线管道!B:C,2,FALSE) -> 一级 | C17: =VLOOKUP(E17,[1]站场阀室!A:D,3,FALSE) -> 西气东输一线 | D17: 西一线干线新疆段 | E17: 雅满苏压气站 | F17: 1+1 | G17: 2# | H17: 39262 | I17: 燃驱 | J17: 进口 | K17: General Electric | L17: PCL804 | M17: PGT25+SAC/GE | N17: 3965-6100 | O17: 6405 | P17: >5.8 | Q17: 31.364 | R17: 投产 | T17: 一期
A18: 甘肃公司 | B18: =VLOOKUP(C18,[1]干线管道!B:C,2,FALSE) -> 一级 | C18: =VLOOKUP(E18,[1]站场阀室!A:D,3,FALSE) -> 西气东输一线 | D18: =VLOOKUP(E18,[1]站场阀室!A:D,4,FALSE) -> 西一线干线甘肃段 | E18: 红柳压气站 | F18: 2+1 | G18: 1# | H18: 38607 | I18: 燃驱 | J18: 进口 | K18: Rolls-Royce | L18: RF2BB36 | M18: RB211-24G/RR | N18: 3120-4800 | O18: 5040 | P18: >4 | Q18: 29.53 | R18: 投产 | S18: 无 | T18: 一期
A19: 甘肃公司 | B19: =VLOOKUP(C19,[1]干线管道!B:C,2,FALSE) -> 一级 | C19: =VLOOKUP(E19,[1]站场阀室!A:D,3,FALSE) -> 西气东输一线 | D19: =VLOOKUP(E19,[1]站场阀室!A:D,4,FALSE) -> 西一线干线甘肃段 | E19: 红柳压气站 | F19: 2+1 | G19: 2# | H19: 38607 | I19: 燃驱 | J19: 进口 | K19: Rolls-Royce | L19: RF2BB36 | M19: RB211-24G/RR | N19: 3120-4800 | O19: 5040 | P19: >4 | Q19: 29.53 | R19: 投产 | T19: 一期
A20: 甘肃公司 | B20: =VLOOKUP(C20,[1]干线管道!B:C,2,FALSE) -> 一级 | C20: =VLOOKUP(E20,[1]站场阀室!A:D,3,FALSE) -> 西气东输一线 | D20: =VLOOKUP(E20,[1]站场阀室!A:D,4,FALSE) -> 西一线干线甘肃段 | E20: 红柳压气站 | F20: 2+1 | G20: 3# | H20: 40494 | I20: 燃驱 | J20: 进口 | K20: Rolls-Royce | L20: RF2BB36 | M20: RB211-24G/RR | N20: 3120-4800 | O20: 5040 | P20: >4 | Q20: 29.53 | R20: 投产 | T20: 一期
A21: 甘肃公司 | B21: =VLOOKUP(C21,[1]干线管道!B:C,2,FALSE) -> 一级 | C21: =VLOOKUP(E21,[1]站场阀室!A:D,3,FALSE) -> 西气东输一线 | D21: =VLOOKUP(E21,[1]站场阀室!A:D,4,FALSE) -> 西一线干线甘肃段 | E21: 柳园压气站 | F21: 2+1 | G21: 1# | H21: 39083 | I21: 燃驱 | J21: 进口 | K21: General Electric | L21: PCL804 | M21: PGT25+SAC/GE | N21: 3965-6100 | O21: 6405 | P21: >5.8 | Q21: 31.364 | R21: 投产 | S21: 无 | T21: 一期
A22: 甘肃公司 | B22: =VLOOKUP(C22,[1]干线管道!B:C,2,FALSE) -> 一级 | C22: =VLOOKUP(E22,[1]站场阀室!A:D,3,FALSE) -> 西气东输一线 | D22: =VLOOKUP(E22,[1]站场阀室!A:D,4,FALSE) -> 西一线干线甘肃段 | E22: 柳园压气站 | F22: 2+1 | G22: 2# | H22: 39090 | I22: 燃驱 | J22: 进口 | K22: General Electric | L22: PCL804 | M22: PGT25+SAC/GE | N22: 3965-6100 | O22: 6405 | P22: >5.8 | Q22: 31.364 | R22: 投产 | T22: 一期
A23: 甘肃公司 | B23: =VLOOKUP(C23,[1]干线管道!B:C,2,FALSE) -> 一级 | C23: =VLOOKUP(E23,[1]站场阀室!A:D,3,FALSE) -> 西气东输一线 | D23: =VLOOKUP(E23,[1]站场阀室!A:D,4,FALSE) -> 西一线干线甘肃段 | E23: 柳园压气站 | F23: 2+1 | G23: 3# | H23: 40490 | I23: 燃驱 | J23: 进口 | K23: General Electric | L23: PCL804 | M23: PGT25+SAC/GE | N23: 3965-6100 | O23: 6405 | P23: >5.8 | Q23: 31.364 | R23: 投产 | T23: 一期
A24: 甘肃公司 | B24: =VLOOKUP(C24,[1]干线管道!B:C,2,FALSE) -> 一级 | C24: =VLOOKUP(E24,[1]站场阀室!A:D,3,FALSE) -> 西气东输一线 | D24: =VLOOKUP(E24,[1]站场阀室!A:D,4,FALSE) -> 西一线干线甘肃段 | E24: 玉门压气站 | F24: 2+1 | G24: 1# | H24: 39256 | I24: 电驱 | J24: 进口 | K24: Rolls-Royce | L24: RF3BB36 | M24: 1DX 1749-8ES01-Z/西门子 西门子变频器 | N24: 3120-4800 | O24: 5040 | P24: >4 | Q24: 22 | R24: 投产 | S24: 无 | T24: 一期
A25: 甘肃公司 | B25: =VLOOKUP(C25,[1]干线管道!B:C,2,FALSE) -> 一级 | C25: =VLOOKUP(E25,[1]站场阀室!A:D,3,FALSE) -> 西气东输一线 | D25: =VLOOKUP(E25,[1]站场阀室!A:D,4,FALSE) -> 西一线干线甘肃段 | E25: 玉门压气站 | F25: 2+1 | G25: 2# | H25: 38671 | I25: 燃驱 | J25: 进口 | K25: Rolls-Royce | L25: RF2BB36 | M25: RB211-24G/RR | N25: 3120-4800 | O25: 5040 | P25: >4 | Q25: 29.53 | R25: 投产 | T25: 一期
A26: 甘肃公司 | B26: =VLOOKUP(C26,[1]干线管道!B:C,2,FALSE) -> 一级 | C26: =VLOOKUP(E26,[1]站场阀室!A:D,3,FALSE) -> 西气东输一线 | D26: =VLOOKUP(E26,[1]站场阀室!A:D,4,FALSE) -> 西一线干线甘肃段 | E26: 玉门压气站 | F26: 2+1 | G26: 3# | H26: 2010.12 | I26: 电驱 | J26: 进口 | K26: Rolls-Royce | L26: RF3BB36 | M26: 1DX 1749-8ES01-Z/西门子 西门子变频器 | N26: 3120-4800 | O26: 5040 | P26: >4 | Q26: 22 | R26: 投产 | T26: 一期
A27: 甘肃公司 | B27: =VLOOKUP(C27,[1]干线管道!B:C,2,FALSE) -> 一级 | C27: =VLOOKUP(E27,[1]站场阀室!A:D,3,FALSE) -> 西气东输一线 | D27: =VLOOKUP(E27,[1]站场阀室!A:D,4,FALSE) -> 西一线干线甘肃段 | E27: 酒泉压气站 | F27: 2+1 | G27: 1# | H27: 39125 | I27: 燃驱 | J27: 进口 | K27: General Electric | L27: PCL804 | M27: PGT25+SAC/GE | N27: 3965-6100 | O27: 6405 | P27: >5.8 | Q27: 31.364 | R27: 投产 | S27: 无 | T27: 一期
A28: 甘肃公司 | B28: =VLOOKUP(C28,[1]干线管道!B:C,2,FALSE) -> 一级 | C28: =VLOOKUP(E28,[1]站场阀室!A:D,3,FALSE) -> 西气东输一线 | D28: =VLOOKUP(E28,[1]站场阀室!A:D,4,FALSE) -> 西一线干线甘肃段 | E28: 酒泉压气站 | F28: 2+1 | G28: 2# | H28: 39125 | I28: 燃驱 | J28: 进口 | K28: General Electric | L28: PCL804 | M28: PGT25+SAC/GE | N28: 3965-6100 | O28: 6405 | P28: >5.8 | Q28: 31.364 | R28: 投产 | T28: 一期
A29: 甘肃公司 | B29: =VLOOKUP(C29,[1]干线管道!B:C,2,FALSE) -> 一级 | C29: =VLOOKUP(E29,[1]站场阀室!A:D,3,FALSE) -> 西气东输一线 | D29: =VLOOKUP(E29,[1]站场阀室!A:D,4,FALSE) -> 西一线干线甘肃段 | E29: 酒泉压气站 | F29: 2+1 | G29: 3# | H29: 40494 | I29: 燃驱 | J29: 进口 | K29: General Electric | L29: PCL804 | M29: PGT25+SAC/GE | N29: 3965-6100 | O29: 6405 | P29: >5.8 | Q29: 31.364 | R29: 投产 | T29: 一期
A30: 甘肃公司 | B30: =VLOOKUP(C30,[1]干线管道!B:C,2,FALSE) -> 一级 | C30: =VLOOKUP(E30,[1]站场阀室!A:D,3,FALSE) -> 西气东输一线 | D30: =VLOOKUP(E30,[1]站场阀室!A:D,4,FALSE) -> 西一线干线甘肃段 | E30: 山丹压气站 | F30: 2+1 | G30: 1# | H30: 39063 | I30: 燃驱 | J30: 进口 | K30: Rolls-Royce | L30: RF3BB36 | M30: RB211-24G/RR | N30: 3120-4800 | O30: 5040 | P30: >4 | Q30: 29.53 | R30: 投产 | S30: 无 | T30: 一期
A31: 甘肃公司 | B31: =VLOOKUP(C31,[1]干线管道!B:C,2,FALSE) -> 一级 | C31: =VLOOKUP(E31,[1]站场阀室!A:D,3,FALSE) -> 西气东输一线 | D31: =VLOOKUP(E31,[1]站场阀室!A:D,4,FALSE) -> 西一线干线甘肃段 | E31: 山丹压气站 | F31: 2+1 | G31: 2# | H31: 38565 | I31: 燃驱 | J31: 进口 | K31: Rolls-Royce | L31: RF3BB36 | M31: RB211-24G/RR | N31: 3120-4800 | O31: 5040 | P31: >4 | Q31: 29.53 | R31: 投产 | T31: 一期
A32: 甘肃公司 | B32: =VLOOKUP(C32,[1]干线管道!B:C,2,FALSE) -> 一级 | C32: =VLOOKUP(E32,[1]站场阀室!A:D,3,FALSE) -> 西气东输一线 | D32: =VLOOKUP(E32,[1]站场阀室!A:D,4,FALSE) -> 西一线干线甘肃段 | E32: 山丹压气站 | F32: 2+1 | G32: 3# | H32: 40483 | I32: 燃驱 | J32: 进口 | K32: Rolls-Royce | L32: RF3BB36 | M32: RB211-24G/RR | N32: 3120-4800 | O32: 5040 | P32: >4 | Q32: 29.53 | R32: 投产 | T32: 一期
A33: 甘肃公司 | B33: =VLOOKUP(C33,[1]干线管道!B:C,2,FALSE) -> 一级 | C33: =VLOOKUP(E33,[1]站场阀室!A:D,3,FALSE) -> 西气东输一线 | D33: =VLOOKUP(E33,[1]站场阀室!A:D,4,FALSE) -> 西一线干线甘肃段 | E33: 金昌压气站 | F33: 1+1 | G33: 1# | H33: 39243 | I33: 燃驱 | J33: 进口 | K33: General Electric | L33: PCL804 | M33: PGT25+SAC/GE | N33: 3965-6100 | O33: 6405 | P33: >5.8 | Q33: 31.364 | R33: 投产 | S33: 无 | T33: 一期
A34: 甘肃公司 | B34: =VLOOKUP(C34,[1]干线管道!B:C,2,FALSE) -> 一级 | C34: =VLOOKUP(E34,[1]站场阀室!A:D,3,FALSE) -> 西气东输一线 | D34: =VLOOKUP(E34,[1]站场阀室!A:D,4,FALSE) -> 西一线干线甘肃段 | E34: 金昌压气站 | F34: 1+1 | G34: 2# | H34: 39337 | I34: 燃驱 | J34: 进口 | K34: General Electric | L34: PCL804 | M34: PGT25+SAC/GE | N34: 3965-6100 | O34: 6405 | P34: >5.8 | Q34: 31.364 | R34: 投产 | T34: 一期
A35: 甘肃公司 | B35: =VLOOKUP(C35,[1]干线管道!B:C,2,FALSE) -> 一级 | C35: =VLOOKUP(E35,[1]站场阀室!A:D,3,FALSE) -> 西气东输一线 | D35: =VLOOKUP(E35,[1]站场阀室!A:D,4,FALSE) -> 西一线干线甘肃段 | E35: 古浪压气站 | F35: 1+1 | G35: １＃ | H35: 39073 | I35: 燃驱 | J35: 进口 | K35: General Electric | L35: PCL804 | M35: PGT25+SAC/GE | N35: 3965-6100 | O35: 6405 | P35: >5.8 | Q35: 31.364 | R35: 投产 | S35: 无 | T35: 一期
A36: 甘肃公司 | B36: =VLOOKUP(C36,[1]干线管道!B:C,2,FALSE) -> 一级 | C36: =VLOOKUP(E36,[1]站场阀室!A:D,3,FALSE) -> 西气东输一线 | D36: =VLOOKUP(E36,[1]站场阀室!A:D,4,FALSE) -> 西一线干线甘肃段 | E36: 古浪压气站 | F36: 1+1 | G36: ２＃ | H36: 39044 | I36: 燃驱 | J36: 进口 | K36: General Electric | L36: PCL804 | M36: PGT25+SAC/GE | N36: 3965-6100 | O36: 6405 | P36: >5.8 | Q36: 31.364 | R36: 投产 | T36: 一期
A37: 西北公司 | B37: =VLOOKUP(C37,[1]干线管道!B:C,2,FALSE) -> 一级 | C37: =VLOOKUP(E37,[1]站场阀室!A:D,3,FALSE) -> 西气东输一线 | D37: =VLOOKUP(E37,[1]站场阀室!A:D,4,FALSE) -> 西一线干线东段 | E37: 中卫压气站 | F37: 1+1 | G37: 1# | H37: 38995 | I37: 燃驱 | J37: 进口 | K37: Rolls-Royce | L37: RF2BB36 | M37: RB211-24G/RR | N37: 3120-4800 | O37: 5040 | P37: >4 | Q37: 29.53 | R37: 投产 | S37: 有 | T37: 一期 | U37: 有余热发电
A38: 西北公司 | B38: =VLOOKUP(C38,[1]干线管道!B:C,2,FALSE) -> 一级 | C38: =VLOOKUP(E38,[1]站场阀室!A:D,3,FALSE) -> 西气东输一线 | D38: =VLOOKUP(E38,[1]站场阀室!A:D,4,FALSE) -> 西一线干线东段 | E38: 中卫压气站 | F38: 1+1 | G38: 2# | H38: 38628 | I38: 燃驱 | J38: 进口 | K38: Rolls-Royce | L38: RF2BB36 | M38: RB211-24G/RR | N38: 3120-4800 | O38: 5040 | P38: >4 | Q38: 29.53 | R38: 投产 | T38: 一期
A39: 西北公司 | B39: =VLOOKUP(C39,[1]干线管道!B:C,2,FALSE) -> 一级 | C39: =VLOOKUP(E39,[1]站场阀室!A:D,3,FALSE) -> 西气东输一线 | D39: =VLOOKUP(E39,[1]站场阀室!A:D,4,FALSE) -> 西一线干线东段 | E39: 西一盐池压气站 | F39: 2+1 | G39: 1# | H39: 39140 | I39: 燃驱 | J39: 进口 | K39: General Electric | L39: PCL804/NP | M39: PGT25+SAC/GE | N39: 3965-6100 | O39: 6405 | P39: >5.8 | Q39: 31.364 | R39: 投产 | S39: 无 | T39: 一期
A40: 西北公司 | B40: =VLOOKUP(C40,[1]干线管道!B:C,2,FALSE) -> 一级 | C40: =VLOOKUP(E40,[1]站场阀室!A:D,3,FALSE) -> 西气东输一线 | D40: =VLOOKUP(E40,[1]站场阀室!A:D,4,FALSE) -> 西一线干线东段 | E40: 西一盐池压气站 | F40: 2+1 | G40: 2# | H40: 39141 | I40: 燃驱 | J40: 进口 | K40: General Electric | L40: PCL804/NP | M40: PGT25+SAC/GE | N40: 3965-6100 | O40: 6405 | P40: >5.8 | Q40: 31.364 | R40: 投产 | T40: 一期
...

Sheet 储气库
A1: [原始]序号 | B1: [原始]名称 | D1: [原始]类型 | E1: [原始]投产时间 | F1: [原始]设计工作气量 亿方 | G1: [原始]当前最大采气能力 万方/日 | H1: [原始]当前最大注气能力 万方/日 | I1: [原始]所属企业
A2: 1 | B2: 大港 | C2: 大张坨 | D2: 枯竭凝析气藏 | E2: 36831 | F2: 30.3 | G2: 2400 | H2: 1500 | I2: 合资
C3: 板876 | E3: 37325
C4: 板中北 | E4: 37802
C5: 板中南 | E5: 38558
C6: 板808 | E6: 2006年9月30日
C7: 板828 | E7: 38990
A8: 2 | B8: 华北 | C8: 京58 | D8: 气顶油气藏 | E8: 40391 | F8: 7.5 | G8: 420 | H8: 420 | I8: 合资
C9: 京51 | D9: 枯竭凝析气藏
C10: 永22 | D10: 含硫化氢凝析气藏
A11: 3 | B11: 刘庄 | D11: 枯竭油气藏 | E11: 40848 | F11: 2.4 | G11: 100 | H11: 150 | I11: 国家管网
A12: 4 | B12: 国网金坛 | C12: 金坛东 | D12: 盐穴 | E12: 39264 | F12: 17.1 | G12: 1500 | H12: 820 | I12: 国家管网
C13: 金坛西 | E13: 41539
A14: 5 | B14: 文23 | D14: 枯竭气藏 | E14: 43677 | F14: 32.7 | G14: 2600 | H14: 1800 | I14: 国家管网
A15: 6 | B15: 呼图壁 | D15: 废弃气藏 | E15: 41434 | F15: 45.1 | G15: 3300 | H15: 1550 | I15: 合资
A16: 7 | B16: 相国寺 | D16: 枯竭油气藏 | E16: 41456 | F16: 28 | G16: 2700 | H16: 1500 | I16: 合资
A17: 8 | B17: 双坨子 | E17: 44105 | F17: 11.2 | G17: 200 | I17: 中石油
A18: 9 | B18: 板南 | D18: 枯竭油气藏 | E18: 41806 | F18: 5.6 | G18: 430 | H18: 310 | I18: 中石油
A19: 10 | B19: 苏桥 | D19: 浅山气藏 | E19: 41439 | F19: 23.3 | G19: 1500 | H19: 1000 | I19: 中石油
A20: 11 | B20: 温吉桑 | D20: 枯竭油气藏 | E20: 44806 | F20: 5.5 | G20: 40 | H20: 330 | I20: 中石油
A21: 12 | B21: 文96 | D21: 枯竭气藏 | F21: 2.9 | G21: 200 | H21: 180 | I21: 中石化
A22: 13 | B22: 中石化金坛 | D22: 盐穴 | E22: 42520 | F22: 7.2 | G22: 200 | H22: 300 | I22: 中石化
A23: 14 | B23: 卫11 | D23: 枯竭油藏 | E23: 44478 | F23: 5.1 | G23: 200 | H23: 350 | I23: 中石化
A24: 15 | B24: 白9 | D24: 枯竭油气藏 | E24: 44652 | F24: 1.54 | G24: 50 | H24: 80 | I24: 中石化
A25: 16 | B25: 清溪 | D25: 枯竭油气藏 | E25: 44491 | F25: 1.94 | G25: 50 | H25: 80 | I25: 中石化
A26: 17 | B26: 江汉 | D26: 盐穴 | E26: 44708 | F26: 1.4 | G26: 20 | H26: 20 | I26: 中石化
A27: 18 | B27: 港华金坛 | D27: 盐穴 | E27: 43374 | F27: 3.1 | G27: 400 | H27: 210 | I27: 港华
A28: 19 | B28: 华北 | D28: 枯竭油气藏 | E28: 40391 | F28: 7.8 | G28: 600 | H28: 540 | I28: 合资
A29: 20 | B29: 双台子（双六） | D29: 枯竭油气藏 | E29: 双六2015年3月/双台子2022年5月 | F29: 54.1 | G29: 3300 | H29: 2600 | I29: 合资
A30: 21 | B30: 白浅
